Workbook

Sheet PERBANDINGAN JUMLAH
A1: KODE | B1: INSTANSI | C1: JENIS ASN | D1: JENIS KELAMIN ASN | E1: GOLONGAN ASN | F1: PENDIDIKAN ASN | G1: USIA ASN | H1: GENERASI ASN | I1: JABATAN ASN | J1: MASA KERJA ASN | K1: KELOMPOK JABATAN | L1: KESESUAIAN JUMLAH
M2: SELISIH
A3: 3003 | B3: Kementerian Pertahanan | C3: ='JENIS ASN'!F6 -> 2806 | D3: ='JENKEL ASN'!H7 -> 2806 | E3: ='GOLONGAN ASN'!Q7 -> 2806 | F3: ='PENDIDIKAN ASN'!V7 -> 2806 | G3: ='USIA ASN'!L7 -> 2806 | H3: ='GEN ASN'!H6 -> 2806 | I3: ='GA DIPAKE JABATAN ASN'!G7 -> 0 | J3: ='MASA KERJA ASN'!H6 -> 2806 | K3: 2806 | L3: =IF(AND(C3=D3 , C3=E3 , C3=F3 , C3=G3 , C3=H3 , C3=J3), "Y", "X") -> Y | M3: ALL | N3: SESUAI | O3: TIDAK SESUAI | P3: TOTAL | Q3: PERSENTASE
A4: 3005 | B4: Kementerian Keuangan | C4: ='JENIS ASN'!F7 -> 3013 | D4: ='JENKEL ASN'!H8 -> 3013 | E4: ='GOLONGAN ASN'!Q8 -> 3013 | F4: ='PENDIDIKAN ASN'!V8 -> 3013 | G4: ='USIA ASN'!L8 -> 3013 | H4: ='GEN ASN'!H7 -> 3013 | I4: ='GA DIPAKE JABATAN ASN'!G8 -> 0 | J4: ='MASA KERJA ASN'!H7 -> 3013 | K4: 3013 | L4: =IF(AND(C4=D4 , C4=E4 , C4=F4 , C4=G4 , C4=H4 , C4=J4), "Y", "X") -> Y | N4: =COUNTIF($L$3:$L$59 , "Y") -> 46 | O4: =COUNTIF(L3:L59 , "X") -> 6 | P4: =SUM(N4:O4) -> 52 | Q4: =N4/P4*100 -> 88.461538
A5: 3006 | B5: Kementerian Pertanian | C5: ='JENIS ASN'!F8 -> 1622 | D5: ='JENKEL ASN'!H9 -> 1622 | E5: ='GOLONGAN ASN'!Q9 -> 1622 | F5: ='PENDIDIKAN ASN'!V9 -> 1622 | G5: ='USIA ASN'!L9 -> 1622 | H5: ='GEN ASN'!H8 -> 1622 | I5: ='GA DIPAKE JABATAN ASN'!G9 -> 0 | J5: ='MASA KERJA ASN'!H8 -> 1622 | K5: 1622 | L5: =IF(AND(C5=D5 , C5=E5 , C5=F5 , C5=G5 , C5=H5 , C5=J5), "Y", "X") -> Y
A6: 3012 | B6: Kementerian Agama | C6: ='JENIS ASN'!F9 -> 26106 | D6: ='JENKEL ASN'!H10 -> 26106 | E6: ='GOLONGAN ASN'!Q10 -> 26106 | F6: ='PENDIDIKAN ASN'!V10 -> 26106 | G6: ='USIA ASN'!L10 -> 26106 | H6: ='GEN ASN'!H9 -> 26106 | I6: ='GA DIPAKE JABATAN ASN'!G10 -> 0 | J6: ='MASA KERJA ASN'!H9 -> 26106 | K6: 26106 | L6: =IF(AND(C6=D6 , C6=E6 , C6=F6 , C6=G6 , C6=H6 , C6=J6), "Y", "X") -> Y
A7: 3024 | B7: Kementerian Imigrasi dan Pemasyarakatan | C7: ='JENIS ASN'!F10 -> 32 | D7: ='JENKEL ASN'!H11 -> 32 | E7: ='GOLONGAN ASN'!Q11 -> 32 | F7: ='PENDIDIKAN ASN'!V11 -> 32 | G7: ='USIA ASN'!L11 -> 32 | H7: ='GEN ASN'!H10 -> 32 | I7: ='GA DIPAKE JABATAN ASN'!G11 -> 0 | J7: ='MASA KERJA ASN'!H10 -> 32 | K7: 3657 | L7: =IF(AND(C7=D7 , C7=E7 , C7=F7 , C7=G7 , C7=H7 , C7=J7), "Y", "X") -> Y
A8: 3038 | B8: Kementerian Hukum | C8: ='JENIS ASN'!F11 -> 3657 | D8: ='JENKEL ASN'!H12 -> 3657 | E8: ='GOLONGAN ASN'!Q12 -> 3657 | F8: ='PENDIDIKAN ASN'!V12 -> 3657 | G8: ='USIA ASN'!L12 -> 3657 | H8: ='GEN ASN'!H11 -> 3657 | I8: ='GA DIPAKE JABATAN ASN'!G12 -> 0 | J8: ='MASA KERJA ASN'!H11 -> 3657 | K8: 200 | L8: =IF(AND(C8=D8 , C8=E8 , C8=F8 , C8=G8 , C8=H8 , C8=J8), "Y", "X") -> Y
A9: 4002 | B9: Kejaksaan Agung | C9: ='JENIS ASN'!F12 -> 200 | D9: ='JENKEL ASN'!H13 -> 200 | E9: ='GOLONGAN ASN'!Q13 -> 200 | F9: ='PENDIDIKAN ASN'!V13 -> 200 | G9: ='USIA ASN'!L13 -> 200 | H9: ='GEN ASN'!H12 -> 200 | I9: ='GA DIPAKE JABATAN ASN'!G13 -> 0 | J9: ='MASA KERJA ASN'!H12 -> 200 | K9: 63 | L9: =IF(AND(C9=D9 , C9=E9 , C9=F9 , C9=G9 , C9=H9 , C9=J9), "Y", "X") -> Y
A10: 4007 | B10: Mahkamah Agung RI | C10: ='JENIS ASN'!F13 -> 63 | D10: ='JENKEL ASN'!H14 -> 63 | E10: ='GOLONGAN ASN'!Q14 -> 63 | F10: ='PENDIDIKAN ASN'!V14 -> 63 | G10: ='USIA ASN'!L14 -> 63 | H10: ='GEN ASN'!H13 -> 63 | I10: ='GA DIPAKE JABATAN ASN'!G15 -> 0 | J10: ='MASA KERJA ASN'!H13 -> 63 | K10: 2368 | L10: =IF(AND(C10=D10 , C10=E10 , C10=F10 , C10=G10 , C10=H10 , C10=J10), "Y", "X") -> Y
A11: 4008 | B11: Badan Pemeriksa Keuangan | C11: ='JENIS ASN'!F14 -> 2368 | D11: ='JENKEL ASN'!H15 -> 2368 | E11: ='GOLONGAN ASN'!Q15 -> 2368 | F11: ='PENDIDIKAN ASN'!V16 -> 239 | G11: ='USIA ASN'!L16 -> 239 | H11: ='GEN ASN'!H14 -> 2368 | I11: ='GA DIPAKE JABATAN ASN'!G16 -> 0 | J11: ='MASA KERJA ASN'!H15 -> 239 | K11: 239 | L11: =IF(AND(C11=D11 , C11=E11 , C11=F11 , C11=G11 , C11=H11 , C11=J11), "Y", "X") -> X
A12: 4016 | B12: Badan Pusat Statistik | C12: ='JENIS ASN'!F15 -> 239 | D12: ='JENKEL ASN'!H17 -> 1286 | E12: ='GOLONGAN ASN'!Q16 -> 239 | F12: ='PENDIDIKAN ASN'!V17 -> 1286 | G12: ='USIA ASN'!L17 -> 1286 | H12: ='GEN ASN'!H15 -> 239 | I12: ='GA DIPAKE JABATAN ASN'!G17 -> 0 | J12: ='MASA KERJA ASN'!H16 -> 1286 | K12: 1286 | L12: =IF(AND(C12=D12 , C12=E12 , C12=F12 , C12=G12 , C12=H12 , C12=J12), "Y", "X") -> X
A13: 4020 | B13: Kementerian Kependudukan Dan Pembangunan Keluarga/Badan Kependudukan Dan Keluarga Berencana Nasional | C13: ='JENIS ASN'!F16 -> 1286 | D13: ='JENKEL ASN'!H18 -> 1746 | E13: ='GOLONGAN ASN'!Q18 -> 1746 | F13: ='PENDIDIKAN ASN'!V18 -> 1746 | G13: ='USIA ASN'!L18 -> 1746 | H13: ='GEN ASN'!H16 -> 1286 | I13: ='GA DIPAKE JABATAN ASN'!G18 -> 0 | J13: ='MASA KERJA ASN'!H17 -> 1746 | K13: 1746 | L13: =IF(AND(C13=D13 , C13=E13 , C13=F13 , C13=G13 , C13=H13 , C13=J13), "Y", "X") -> X
A14: 4023 | B14: Badan Pengawasan Keuangan dan Pembangunan | C14: ='JENIS ASN'!F17 -> 1746 | D14: ='JENKEL ASN'!H19 -> 213 | E14: ='GOLONGAN ASN'!Q19 -> 213 | F14: ='PENDIDIKAN ASN'!V19 -> 213 | G14: ='USIA ASN'!L19 -> 213 | H14: ='GEN ASN'!H17 -> 1746 | I14: ='GA DIPAKE JABATAN ASN'!G19 -> 0 | J14: ='MASA KERJA ASN'!H18 -> 213 | K14: 213 | L14: =IF(AND(C14=D14 , C14=E14 , C14=F14 , C14=G14 , C14=H14 , C14=J14), "Y", "X") -> X
A15: 4024 | B15: Kementerian Agraria dan Tata Ruang/Badan Pertanahan Nasional | C15: ='JENIS ASN'!F18 -> 213 | D15: ='JENKEL ASN'!H20 -> 206 | E15: ='GOLONGAN ASN'!Q20 -> 206 | F15: ='PENDIDIKAN ASN'!V20 -> 206 | G15: ='USIA ASN'!L20 -> 206 | H15: ='GEN ASN'!H19 -> 206 | I15: ='GA DIPAKE JABATAN ASN'!G20 -> 0 | J15: ='MASA KERJA ASN'!H19 -> 206 | K15: 206 | L15: =IF(AND(C15=D15 , C15=E15 , C15=F15 , C15=G15 , C15=H15 , C15=J15), "Y", "X") -> X
A16: 4033 | B16: Kepolisian Negara | C16: ='JENIS ASN'!F19 -> 206 | D16: ='JENKEL ASN'!H21 -> 925 | E16: ='GOLONGAN ASN'!Q21 -> 925 | F16: ='PENDIDIKAN ASN'!V21 -> 925 | G16: ='USIA ASN'!L21 -> 925 | H16: ='GEN ASN'!H20 -> 925 | I16: ='GA DIPAKE JABATAN ASN'!G21 -> 0 | J16: ='MASA KERJA ASN'!H20 -> 925 | K16: 925 | L16: =IF(AND(C16=D16 , C16=E16 , C16=F16 , C16=G16 , C16=H16 , C16=J16), "Y", "X") -> X
A17: 4071 | B17: Badan Karantina Indonesia | C17: ='JENIS ASN'!F21 -> 395 | D17: ='JENKEL ASN'!H22 -> 395 | E17: ='GOLONGAN ASN'!Q22 -> 395 | F17: ='PENDIDIKAN ASN'!V22 -> 395 | G17: ='USIA ASN'!L22 -> 395 | H17: ='GEN ASN'!H21 -> 395 | I17: ='GA DIPAKE JABATAN ASN'!G22 -> 0 | J17: ='MASA KERJA ASN'!H21 -> 395 | K17: 395 | L17: =IF(AND(C17=D17 , C17=E17 , C17=F17 , C17=G17 , C17=H17 , C17=J17), "Y", "X") -> Y
C18: =sum(C3:C17) -> 43952 | D18: =sum(D3:D17) -> 44638 | E18: =sum(E3:E17) -> 43591 | F18: =sum(F3:F17) -> 42509 | G18: =sum(G3:G17) -> 42509 | H18: =sum(H3:H17) -> 44664 | I18: =sum(I3:I17) -> 0 | J18: =sum(J3:J17) -> 42509
A19: 6100 | B19: Pemerintah Provinsi Jawa Barat | C19: ='JENIS ASN'!F23 -> 52472 | D19: ='JENKEL ASN'!H24 -> 52472 | E19: ='GOLONGAN ASN'!Q24 -> 52472 | F19: ='PENDIDIKAN ASN'!V24 -> 52472 | G19: ='USIA ASN'!L24 -> 52472 | H19: ='GEN ASN'!H23 -> 52472 | I19: ='GA DIPAKE JABATAN ASN'!G24 | J19: ='MASA KERJA ASN'!H23 -> 52472 | K19: ='KEL JABATAN FIX'!X19 -> 52472 | L19: =IF(AND(C19=D19 , C19=E19 , C19=F19 , C19=G19 , C19=H19 , C19=C19 , J19=K19), "Y", "X") -> Y | M19: =J19-K19 -> 0
A20: 6101 | B20: Pemerintah Kab. Bogor | C20: ='JENIS ASN'!F24 -> 25862 | D20: ='JENKEL ASN'!H25 -> 25862 | E20: ='GOLONGAN ASN'!Q25 -> 25862 | F20: ='PENDIDIKAN ASN'!V25 -> 25862 | G20: ='USIA ASN'!L25 -> 25862 | H20: ='GEN ASN'!H24 -> 25862 | I20: ='GA DIPAKE JABATAN ASN'!G25 | J20: ='MASA KERJA ASN'!H24 -> 25862 | K20: ='KEL JABATAN FIX'!X20 -> 25862 | L20: =IF(AND(C20=D20 , C20=E20 , C20=F20 , C20=G20 , C20=H20 , C20=C20 , J20=K20), "Y", "X") -> Y | M20: =J20-K20 -> 0
A21: 6102 | B21: Pemerintah Kab. Sukabumi | C21: ='JENIS ASN'!F25 -> 13071 | D21: ='JENKEL ASN'!H26 -> 13071 | E21: ='GOLONGAN ASN'!Q26 -> 13071 | F21: ='PENDIDIKAN ASN'!V26 -> 13071 | G21: ='USIA ASN'!L26 -> 13071 | H21: ='GEN ASN'!H25 -> 13071 | I21: ='GA DIPAKE JABATAN ASN'!G26 | J21: ='MASA KERJA ASN'!H25 -> 13071 | K21: ='KEL JABATAN FIX'!X21 -> 13071 | L21: =IF(AND(C21=D21 , C21=E21 , C21=F21 , C21=G21 , C21=H21 , C21=C21 , J21=K21), "Y", "X") -> Y | M21: =J21-K21 -> 0
A22: 6103 | B22: Pemerintah Kab. Cianjur | C22: ='JENIS ASN'!F26 -> 15452 | D22: ='JENKEL ASN'!H27 -> 15452 | E22: ='GOLONGAN ASN'!Q27 -> 15452 | F22: ='PENDIDIKAN ASN'!V27 -> 15452 | G22: ='USIA ASN'!L27 -> 15452 | H22: ='GEN ASN'!H26 -> 15452 | I22: ='GA DIPAKE JABATAN ASN'!G27 | J22: ='MASA KERJA ASN'!H26 -> 15452 | K22: ='KEL JABATAN FIX'!X22 -> 15452 | L22: =IF(AND(C22=D22 , C22=E22 , C22=F22 , C22=G22 , C22=H22 , C22=C22 , J22=K22), "Y", "X") -> Y | M22: =J22-K22 -> 0
A23: 6104 | B23: Pemerintah Kab. Bekasi | C23: ='JENIS ASN'!F27 -> 22459 | D23: ='JENKEL ASN'!H28 -> 22459 | E23: ='GOLONGAN ASN'!Q28 -> 22459 | F23: ='PENDIDIKAN ASN'!V28 -> 22459 | G23: ='USIA ASN'!L28 -> 22459 | H23: ='GEN ASN'!H27 -> 22459 | I23: ='GA DIPAKE JABATAN ASN'!G28 | J23: ='MASA KERJA ASN'!H27 -> 22459 | K23: ='KEL JABATAN FIX'!X23 -> 22459 | L23: =IF(AND(C23=D23 , C23=E23 , C23=F23 , C23=G23 , C23=H23 , C23=C23 , J23=K23), "Y", "X") -> Y | M23: =J23-K23 -> 0 | N23: DAERAH
A24: 6105 | B24: Pemerintah Kab. Karawang | C24: ='JENIS ASN'!F28 -> 13420 | D24: ='JENKEL ASN'!H29 -> 13420 | E24: ='GOLONGAN ASN'!Q29 -> 13420 | F24: ='PENDIDIKAN ASN'!V29 -> 13420 | G24: ='USIA ASN'!L29 -> 13420 | H24: ='GEN ASN'!H28 -> 13420 | I24: ='GA DIPAKE JABATAN ASN'!G29 | J24: ='MASA KERJA ASN'!H28 -> 13420 | K24: ='KEL JABATAN FIX'!X24 -> 13420 | L24: =IF(AND(C24=D24 , C24=E24 , C24=F24 , C24=G24 , C24=H24 , C24=C24 , J24=K24), "Y", "X") -> Y | M24: =J24-K24 -> 0 | N24: SESUAI | O24: TIDAK SESUAI | P24: TOTAL | Q24: PERSENTASE
A25: 6106 | B25: Pemerintah Kab. Purwakarta | C25: ='JENIS ASN'!F29 -> 8007 | D25: ='JENKEL ASN'!H30 -> 8007 | E25: ='GOLONGAN ASN'!Q30 -> 8007 | F25: ='PENDIDIKAN ASN'!V30 -> 8007 | G25: ='USIA ASN'!L30 -> 8007 | H25: ='GEN ASN'!H29 -> 8007 | I25: ='GA DIPAKE JABATAN ASN'!G30 | J25: ='MASA KERJA ASN'!H29 -> 8007 | K25: ='KEL JABATAN FIX'!X25 -> 8007 | L25: =IF(AND(C25=D25 , C25=E25 , C25=F25 , C25=G25 , C25=H25 , C25=C25 , J25=K25), "Y", "X") -> Y | M25: =J25-K25 -> 0 | N25: =COUNTIF($L$19:$L$59 , "Y") -> 37 | O25: =COUNTIF(L19:L59 , "X") -> 0 | P25: =SUM(N25:O25) -> 37 | Q25: =N25/P25*100 -> 100
A26: 6107 | B26: Pemerintah Kab. Subang | C26: ='JENIS ASN'!F30 -> 12233 | D26: ='JENKEL ASN'!H31 -> 12233 | E26: ='GOLONGAN ASN'!Q31 -> 12233 | F26: ='PENDIDIKAN ASN'!V31 -> 12233 | G26: ='USIA ASN'!L31 -> 12233 | H26: ='GEN ASN'!H30 -> 12233 | I26: ='GA DIPAKE JABATAN ASN'!G31 | J26: ='MASA KERJA ASN'!H30 -> 12233 | K26: ='KEL JABATAN FIX'!X26 -> 12233 | L26: =IF(AND(C26=D26 , C26=E26 , C26=F26 , C26=G26 , C26=H26 , C26=C26 , J26=K26), "Y", "X") -> Y | M26: =J26-K26 -> 0
A27: 6108 | B27: Pemerintah Kab. Bandung | C27: ='JENIS ASN'!F31 -> 19158 | D27: ='JENKEL ASN'!H32 -> 19158 | E27: ='GOLONGAN ASN'!Q32 -> 19158 | F27: ='PENDIDIKAN ASN'!V32 -> 19158 | G27: ='USIA ASN'!L32 -> 19158 | H27: ='GEN ASN'!H31 -> 19158 | I27: ='GA DIPAKE JABATAN ASN'!G32 | J27: ='MASA KERJA ASN'!H31 -> 19158 | K27: ='KEL JABATAN FIX'!X27 -> 19158 | L27: =IF(AND(C27=D27 , C27=E27 , C27=F27 , C27=G27 , C27=H27 , C27=C27 , J27=K27), "Y", "X") -> Y | M27: =J27-K27 -> 0
A28: 6109 | B28: Pemerintah Kab. Sumedang | C28: ='JENIS ASN'!F32 -> 9970 | D28: ='JENKEL ASN'!H33 -> 9970 | E28: ='GOLONGAN ASN'!Q33 -> 9970 | F28: ='PENDIDIKAN ASN'!V33 -> 9970 | G28: ='USIA ASN'!L33 -> 9970 | H28: ='GEN ASN'!H32 -> 9970 | I28: ='GA DIPAKE JABATAN ASN'!G33 | J28: ='MASA KERJA ASN'!H32 -> 9970 | K28: ='KEL JABATAN FIX'!X28 -> 9970 | L28: =IF(AND(C28=D28 , C28=E28 , C28=F28 , C28=G28 , C28=H28 , C28=C28 , J28=K28), "Y", "X") -> Y | M28: =J28-K28 -> 0
A29: 6110 | B29: Pemerintah Kab. Garut | C29: ='JENIS ASN'!F33 -> 20154 | D29: ='JENKEL ASN'!H34 -> 20154 | E29: ='GOLONGAN ASN'!Q34 -> 20154 | F29: ='PENDIDIKAN ASN'!V34 -> 20154 | G29: ='USIA ASN'!L34 -> 20154 | H29: ='GEN ASN'!H33 -> 20154 | I29: ='GA DIPAKE JABATAN ASN'!G34 | J29: ='MASA KERJA ASN'!H33 -> 20154 | K29: ='KEL JABATAN FIX'!X29 -> 20154 | L29: =IF(AND(C29=D29 , C29=E29 , C29=F29 , C29=G29 , C29=H29 , C29=C29 , J29=K29), "Y", "X") -> Y | M29: =J29-K29 -> 0
A30: 6111 | B30: Pemerintah Kab. Tasikmalaya | C30: ='JENIS ASN'!F34 -> 12411 | D30: ='JENKEL ASN'!H35 -> 12411 | E30: ='GOLONGAN ASN'!Q35 -> 12411 | F30: ='PENDIDIKAN ASN'!V35 -> 12411 | G30: ='USIA ASN'!L35 -> 12411 | H30: ='GEN ASN'!H34 -> 12411 | I30: ='GA DIPAKE JABATAN ASN'!G35 | J30: ='MASA KERJA ASN'!H34 -> 12411 | K30: ='KEL JABATAN FIX'!X30 -> 12411 | L30: =IF(AND(C30=D30 , C30=E30 , C30=F30 , C30=G30 , C30=H30 , C30=C30 , J30=K30), "Y", "X") -> Y | M30: =J30-K30 -> 0
A31: 6112 | B31: Pemerintah Kab. Ciamis | C31: ='JENIS ASN'!F35 -> 9872 | D31: ='JENKEL ASN'!H36 -> 9872 | E31: ='GOLONGAN ASN'!Q36 -> 9872 | F31: ='PENDIDIKAN ASN'!V36 -> 9872 | G31: ='USIA ASN'!L36 -> 9872 | H31: ='GEN ASN'!H35 -> 9872 | I31: ='GA DIPAKE JABATAN ASN'!G36 | J31: ='MASA KERJA ASN'!H35 -> 9872 | K31: ='KEL JABATAN FIX'!X31 -> 9872 | L31: =IF(AND(C31=D31 , C31=E31 , C31=F31 , C31=G31 , C31=H31 , C31=C31 , J31=K31), "Y", "X") -> Y | M31: =J31-K31 -> 0
A32: 6113 | B32: Pemerintah Kab. Cirebon | C32: ='JENIS ASN'!F36 -> 18473 | D32: ='JENKEL ASN'!H37 -> 18473 | E32: ='GOLONGAN ASN'!Q37 -> 18473 | F32: ='PENDIDIKAN ASN'!V37 -> 18473 | G32: ='USIA ASN'!L37 -> 18473 | H32: ='GEN ASN'!H36 -> 18473 | I32: ='GA DIPAKE JABATAN ASN'!G37 | J32: ='MASA KERJA ASN'!H36 -> 18473 | K32: ='KEL JABATAN FIX'!X32 -> 18473 | L32: =IF(AND(C32=D32 , C32=E32 , C32=F32 , C32=G32 , C32=H32 , C32=C32 , J32=K32), "Y", "X") -> Y | M32: =J32-K32 -> 0
A33: 6114 | B33: Pemerintah Kab. Kuningan | C33: ='JENIS ASN'!F37 -> 11351 | D33: ='JENKEL ASN'!H38 -> 11351 | E33: ='GOLONGAN ASN'!Q38 -> 11351 | F33: ='PENDIDIKAN ASN'!V38 -> 11351 | G33: ='USIA ASN'!L38 -> 11351 | H33: ='GEN ASN'!H37 -> 11351 | I33: ='GA DIPAKE JABATAN ASN'!G38 | J33: ='MASA KERJA ASN'!H37 -> 11351 | K33: ='KEL JABATAN FIX'!X33 -> 11351 | L33: =IF(AND(C33=D33 , C33=E33 , C33=F33 , C33=G33 , C33=H33 , C33=C33 , J33=K33), "Y", "X") -> Y | M33: =J33-K33 -> 0
A34: 6115 | B34: Pemerintah Kab. Indramayu | C34: ='JENIS ASN'!F38 -> 11740 | D34: ='JENKEL ASN'!H39 -> 11740 | E34: ='GOLONGAN ASN'!Q39 -> 11740 | F34: ='PENDIDIKAN ASN'!V39 -> 11740 | G34: ='USIA ASN'!L39 -> 11740 | H34: ='GEN ASN'!H38 -> 11740 | I34: ='GA DIPAKE JABATAN ASN'!G39 | J34: ='MASA KERJA ASN'!H38 -> 11740 | K34: ='KEL JABATAN FIX'!X34 -> 11740 | L34: =IF(AND(C34=D34 , C34=E34 , C34=F34 , C34=G34 , C34=H34 , C34=C34 , J34=K34), "Y", "X") -> Y | M34: =J34-K34 -> 0
A35: 6116 | B35: Pemerintah Kab. Majalengka | C35: ='JENIS ASN'!F39 -> 12088 | D35: ='JENKEL ASN'!H40 -> 12088 | E35: ='GOLONGAN ASN'!Q40 -> 12088 | F35: ='PENDIDIKAN ASN'!V40 -> 12088 | G35: ='USIA ASN'!L40 -> 12088 | H35: ='GEN ASN'!H39 -> 12088 | I35: ='GA DIPAKE JABATAN ASN'!G40 | J35: ='MASA KERJA ASN'!H39 -> 12088 | K35: ='KEL JABATAN FIX'!X35 -> 12088 | L35: =IF(AND(C35=D35 , C35=E35 , C35=F35 , C35=G35 , C35=H35 , C35=C35 , J35=K35), "Y", "X") -> Y | M35: =J35-K35 -> 0
A36: 6117 | B36: Pemerintah Kab. Bandung Barat | C36: ='JENIS ASN'!F40 -> 8473 | D36: ='JENKEL ASN'!H41 -> 8473 | E36: ='GOLONGAN ASN'!Q41 -> 8473 | F36: ='PENDIDIKAN ASN'!V41 -> 8473 | G36: ='USIA ASN'!L41 -> 8473 | H36: ='GEN ASN'!H40 -> 8473 | I36: ='GA DIPAKE JABATAN ASN'!G41 | J36: ='MASA KERJA ASN'!H40 -> 8473 | K36: ='KEL JABATAN FIX'!X36 -> 8473 | L36: =IF(AND(C36=D36 , C36=E36 , C36=F36 , C36=G36 , C36=H36 , C36=C36 , J36=K36), "Y", "X") -> Y | M36: =J36-K36 -> 0
A37: 6118 | B37: Pemerintah Kab. Pangandaran | C37: ='JENIS ASN'!F41 -> 4676 | D37: ='JENKEL ASN'!H42 -> 4676 | E37: ='GOLONGAN ASN'!Q42 -> 4676 | F37: ='PENDIDIKAN ASN'!V42 -> 4676 | G37: ='USIA ASN'!L42 -> 4676 | H37: ='GEN ASN'!H41 -> 4676 | I37: ='GA DIPAKE JABATAN ASN'!G42 | J37: ='MASA KERJA ASN'!H41 -> 4676 | K37: ='KEL JABATAN FIX'!X37 -> 4676 | L37: =IF(AND(C37=D37 , C37=E37 , C37=F37 , C37=G37 , C37=H37 , C37=C37 , J37=K37), "Y", "X") -> Y | M37: =J37-K37 -> 0
... A46: 6179 | B46: Pemerintah Kota Banjar | C46: ='JENIS ASN'!F50 -> 4861 | D46: ='JENKEL ASN'!H51 -> 4861 | E46: ='GOLONGAN ASN'!Q51 -> 4861 | F46: ='PENDIDIKAN ASN'!V51 -> 4861 | G46: ='USIA ASN'!L51 -> 4861 | H46: ='GEN ASN'!H50 -> 4861 | I46: ='GA DIPAKE JABATAN ASN'!G51 | J46: ='MASA KERJA ASN'!H50 -> 4861 | K46: ='KEL JABATAN FIX'!X46 -> 4861 | L46: =IF(AND(C46=D46 , C46=E46 , C46=F46 , C46=G46 , C46=H46 , C46=C46 , J46=K46), "Y", "X") -> Y | M46: =J46-K46 -> 0
A47: JUMLAH SEWILAYAH JAWA BARAT | C47: =sum(C19:C46) -> 378744 | D47: =sum(D19:D46) -> 378744 | E47: =sum(E19:E46) -> 378744 | F47: =sum(F19:F46) -> 378744 | G47: =sum(G19:G46) -> 378744 | H47: =sum(H19:H46) -> 378744 | I47: =sum(I19:I46) -> 0 | J47: =sum(J19:J46) -> 378744 | K47: ='KEL JABATAN FIX'!X47 -> 378744 | M47: =J47-K47 -> 0
A48: 6200 | B48: Pemerintah Provinsi Banten | C48: ='JENIS ASN'!F52 -> 21655 | D48: ='JENKEL ASN'!H53 -> 21655 | E48: ='GOLONGAN ASN'!Q53 -> 21655 | F48: ='PENDIDIKAN ASN'!V53 -> 21655 | G48: ='USIA ASN'!L53 -> 21655 | H48: ='GEN ASN'!H52 -> 21655 | I48: ='GA DIPAKE JABATAN ASN'!G53 | J48: ='MASA KERJA ASN'!H52 -> 21655 | K48: ='KEL JABATAN FIX'!X48 -> 21655 | L48: =IF(AND(C48=D48 , C48=E48 , C48=F48 , C48=G48 , C48=H48 , C48=C48 , J48=K48), "Y", "X") -> Y | M48: =J48-K48 -> 0
...

Sheet JENIS ASN
A1: ASN NOVEMBER 2025
A2: berdasarkan Jenis ASN
A3: keadaan data pada tanggal : 3 November 2025
A5: JENIS | B5: KODE | C5: INSTANSI | D5: PNS | E5: PPPK | F5: JUMLAH | G5: % PNS | H5: % PPPK
A6: INSTANSI PUSAT | B6: 3003 | C6: Kementerian Pertahanan | D6: 1663 | E6: 1143 | F6: =sum(D6:E6) -> 2806 | G6: =D6/F6 -> 0.59265859 | H6: =E6/F6 -> 0.40734141
B7: 3005 | C7: Kementerian Keuangan | D7: 3013 | E7: 0 | F7: =sum(D7:E7) -> 3013 | G7: =D7/F7 -> 1 | H7: =E7/F7 -> 0
B8: 3006 | C8: Kementerian Pertanian | D8: 1622 | E8: 0 | F8: =sum(D8:E8) -> 1622 | G8: =D8/F8 -> 1 | H8: =E8/F8 -> 0
B9: 3012 | C9: Kementerian Agama | D9: 25367 | E9: 739 | F9: =sum(D9:E9) -> 26106 | G9: =D9/F9 -> 0.97169233 | H9: =E9/F9 -> 0.028307669
B10: 3023 | C10: Kementerian Hak Asasi Manusia | D10: 32 | E10: 0 | F10: =sum(D10:E10) -> 32 | G10: =D10/F10 -> 1 | H10: =E10/F10 -> 0
B11: 3024 | C11: Kementerian Imigrasi dan Pemasyarakatan | D11: 3657 | E11: 0 | F11: =sum(D11:E11) -> 3657 | G11: =D11/F11 -> 1 | H11: =E11/F11 -> 0
B12: 3038 | C12: Kementerian Hukum | D12: 200 | E12: 0 | F12: =sum(D12:E12) -> 200 | G12: =D12/F12 -> 1 | H12: =E12/F12 -> 0
B13: 4002 | C13: Kejaksaan Agung | D13: 63 | E13: 0 | F13: =sum(D13:E13) -> 63 | G13: =D13/F13 -> 1 | H13: =E13/F13 -> 0
B14: 4007 | C14: Mahkamah Agung RI | D14: 2364 | E14: 4 | F14: =sum(D14:E14) -> 2368 | G14: =D14/F14 -> 0.99831081 | H14: =E14/F14 -> 0.0016891892
B15: 4008 | C15: Badan Pemeriksa Keuangan | D15: 239 | E15: 0 | F15: =sum(D15:E15) -> 239 | G15: =D15/F15 -> 1 | H15: =E15/F15 -> 0
B16: 4016 | C16: Badan Pusat Statistik | D16: 1279 | E16: 7 | F16: =sum(D16:E16) -> 1286 | G16: =D16/F16 -> 0.99455677 | H16: =E16/F16 -> 0.0054432348
B17: 4020 | C17: Kementerian Kependudukan Dan Pembangunan Keluarga/Badan Kependudukan Dan Keluarga Berencana Nasional | D17: 695 | E17: 1051 | F17: =sum(D17:E17) -> 1746 | G17: =D17/F17 -> 0.39805269 | H17: =E17/F17 -> 0.60194731
B18: 4023 | C18: Badan Pengawasan Keuangan dan Pembangunan | D18: 213 | E18: 0 | F18: =sum(D18:E18) -> 213 | G18: =D18/F18 -> 1 | H18: =E18/F18 -> 0
... B21: 4071 | C21: Badan Karantina Indonesia | D21: 395 | E21: 0 | F21: =sum(D21:E21) -> 395 | G21: =D21/F21 -> 1 | H21: =E21/F21 -> 0
A22: JUMLAH INSTANSI PUSAT | D22: =SUM(D6:D21) -> 41933 | E22: =SUM(E6:E21) -> 2944 | F22: =SUM(F6:F21) -> 44877 | G22: =D22/F22 -> 0.93439847 | H22: =E22/F22 -> 0.065601533
A23: INSTANSI DAERAH | B23: 6100 | C23: Pemerintah Provinsi Jawa Barat | D23: 26774 | E23: 25698 | F23: =sum(D23:E23) -> 52472 | G23: =D23/F23 -> 0.51025309 | H23: =E23/F23 -> 0.48974691
B24: 6101 | C24: Pemerintah Kab. Bogor | D24: 11890 | E24: 13972 | F24: =sum(D24:E24) -> 25862 | G24: =D24/F24 -> 0.45974789 | H24: =E24/F24 -> 0.54025211
B25: 6102 | C25: Pemerintah Kab. Sukabumi | D25: 7937 | E25: 5134 | F25: =sum(D25:E25) -> 13071 | G25: =D25/F25 -> 0.60722209 | H25: =E25/F25 -> 0.39277791
B26: 6103 | C26: Pemerintah Kab. Cianjur | D26: 7312 | E26: 8140 | F26: =sum(D26:E26) -> 15452 | G26: =D26/F26 -> 0.47320735 | H26: =E26/F26 -> 0.52679265
B27: 6104 | C27: Pemerintah Kab. Bekasi | D27: 9045 | E27: 13414 | F27: =sum(D27:E27) -> 22459 | G27: =D27/F27 -> 0.40273387 | H27: =E27/F27 -> 0.59726613
B28: 6105 | C28: Pemerintah Kab. Karawang | D28: 7679 | E28: 5741 | F28: =sum(D28:E28) -> 13420 | G28: =D28/F28 -> 0.57220566 | H28: =E28/F28 -> 0.42779434
B29: 6106 | C29: Pemerintah Kab. Purwakarta | D29: 5739 | E29: 2268 | F29: =sum(D29:E29) -> 8007 | G29: =D29/F29 -> 0.71674785 | H29: =E29/F29 -> 0.28325215
B30: 6107 | C30: Pemerintah Kab. Subang | D30: 8129 | E30: 4104 | F30: =sum(D30:E30) -> 12233 | G30: =D30/F30 -> 0.66451402 | H30: =E30/F30 -> 0.33548598
B31: 6108 | C31: Pemerintah Kab. Bandung | D31: 10294 | E31: 8864 | F31: =sum(D31:E31) -> 19158 | G31: =D31/F31 -> 0.53732122 | H31: =E31/F31 -> 0.46267878
B32: 6109 | C32: Pemerintah Kab. Sumedang | D32: 6533 | E32: 3437 | F32: =sum(D32:E32) -> 9970 | G32: =D32/F32 -> 0.6552658 | H32: =E32/F32 -> 0.3447342
B33: 6110 | C33: Pemerintah Kab. Garut | D33: 10175 | E33: 9979 | F33: =sum(D33:E33) -> 20154 | G33: =D33/F33 -> 0.50486256 | H33: =E33/F33 -> 0.49513744
B34: 6111 | C34: Pemerintah Kab. Tasikmalaya | D34: 7567 | E34: 4844 | F34: =sum(D34:E34) -> 12411 | G34: =D34/F34 -> 0.60970107 | H34: =E34/F34 -> 0.39029893
B35: 6112 | C35: Pemerintah Kab. Ciamis | D35: 5850 | E35: 4022 | F35: =sum(D35:E35) -> 9872 | G35: =D35/F35 -> 0.59258509 | H35: =E35/F35 -> 0.40741491
... B50: 6179 | C50: Pemerintah Kota Banjar | D50: 2611 | E50: 2250 | F50: =sum(D50:E50) -> 4861 | G50: =D50/F50 -> 0.53713228 | H50: =E50/F50 -> 0.46286772
B51: JUMLAH SEWILAYAH JAWA BARAT | D51: =SUM(D23:D50) -> 210911 | E51: =SUM(E23:E50) -> 167833 | F51: =sum(D51:E51) -> 378744 | G51: =D51/F51 -> 0.55686955 | H51: =E51/F51 -> 0.44313045
B52: 6200 | C52: Pemerintah Provinsi Banten | D52: 8280 | E52: 13375 | F52: =sum(D52:E52) -> 21655 | G52: =D52/F52 -> 0.38235973 | H52: =E52/F52 -> 0.61764027
B53: 6201 | C53: Pemerintah Kab. Serang | D53: 7538 | E53: 2633 | F53: =sum(D53:E53) -> 10171 | G53: =D53/F53 -> 0.74112673 | H53: =E53/F53 -> 0.25887327
B54: 6202 | C54: Pemerintah Kab. Pandeglang | D54: 7395 | E54: 5240 | F54: =sum(D54:E54) -> 12635 | G54: =D54/F54 -> 0.58527899 | H54: =E54/F54 -> 0.41472101
B55: 6203 | C55: Pemerintah Kab. Lebak | D55: 7161 | E55: 5223 | F55: =sum(D55:E55) -> 12384 | G55: =D55/F55 -> 0.57824612 | H55: =E55/F55 -> 0.42175388
B56: 6204 | C56: Pemerintah Kab. Tangerang | D56: 9345 | E56: 6515 | F56: =sum(D56:E56) -> 15860 | G56: =D56/F56 -> 0.58921816 | H56: =E56/F56 -> 0.41078184
B57: 6271 | C57: Pemerintah Kota Tangerang | D57: 6135 | E57: 7595 | F57: =sum(D57:E57) -> 13730 | G57: =D57/F57 -> 0.44683176 | H57: =E57/F57 -> 0.55316824
...

Sheet GOLONGAN ASN
A1: ASN OKTOBER 2025
A2: berdasarkan Golongan ASN
A3: keadaan data pada tanggal : 2 November 2025
A5: JENIS | B5: KODE | C5: INSTANSI | D5: PNS | H5: PPPK | Q5: JUMLAH | R5: PPPK
D6: GOLONGAN I | E6: GOLONGAN II | F6: GOLONGAN III | G6: GOLONGAN IV | H6: GOLONGAN I | I6: GOLONGAN III | J6: GOLONGAN V | K6: GOLONGAN VI | L6: GOLONGAN VII | M6: GOLONGAN IX | N6: GOLONGAN X | O6: GOLONGAN XI | P6: GOLONGAN XIII | R6: PPPK GOL I,III | S6: PPPK GOL V,VI, VII | T6: PPPK GOL IX,X,XI,XIII | U6: Jumlah
A7: INSTANSI PUSAT | B7: 3003 | C7: Kementerian Pertahanan | D7: 1 | E7: 722 | F7: 909 | G7: 31 | H7: 0 | I7: 0 | J7: 0 | K7: 0 | L7: 1032 | M7: 17 | N7: 94 | O7: 0 | P7: 0 | Q7: =SUM(D7:P7) -> 2806 | R7: =sum(H7:I7) -> 0 | S7: =sum(J7:L7) -> 1032 | T7: =sum(M7:P7) -> 111 | U7: =sum(D7:G7,R7:T7) -> 2806
B8: 3005 | C8: Kementerian Keuangan | D8: 1 | E8: 1083 | F8: 1687 | G8: 242 | H8: 0 | I8: 0 | J8: 0 | K8: 0 | L8: 0 | M8: 0 | N8: 0 | O8: 0 | P8: 0 | Q8: =SUM(D8:P8) -> 3013 | R8: =sum(H8:I8) -> 0 | S8: =sum(J8:L8) -> 0 | T8: =sum(M8:P8) -> 0 | U8: =sum(D8:G8,R8:T8) -> 3013
B9: 3006 | C9: Kementerian Pertanian | D9: 8 | E9: 355 | F9: 1024 | G9: 235 | H9: 0 | I9: 0 | J9: 0 | K9: 0 | L9: 0 | M9: 0 | N9: 0 | O9: 0 | P9: 0 | Q9: =SUM(D9:P9) -> 1622 | R9: =sum(H9:I9) -> 0 | S9: =sum(J9:L9) -> 0 | T9: =sum(M9:P9) -> 0 | U9: =sum(D9:G9,R9:T9) -> 1622
B10: 3012 | C10: Kementerian Agama | D10: 28 | E10: 562 | F10: 15529 | G10: 9248 | H10: 0 | I10: 0 | J10: 0 | K10: 0 | L10: 0 | M10: 718 | N10: 21 | O10: 0 | P10: 0 | Q10: =SUM(D10:P10) -> 26106 | R10: =sum(H10:I10) -> 0 | S10: =sum(J10:L10) -> 0 | T10: =sum(M10:P10) -> 739 | U10: =sum(D10:G10,R10:T10) -> 26106
B11: 3023 | C11: Kementerian Hak Asasi Manusia | D11: 0 | E11: 5 | F11: 23 | G11: 4 | H11: 0 | I11: 0 | J11: 0 | K11: 0 | L11: 0 | M11: 0 | N11: 0 | O11: 0 | P11: 0 | Q11: =SUM(D11:P11) -> 32 | R11: =sum(H11:I11) -> 0 | S11: =sum(J11:L11) -> 0 | T11: =sum(M11:P11) -> 0 | U11: =sum(D11:G11,R11:T11) -> 32
B12: 3024 | C12: Kementerian Imigrasi dan Pemasyarakatan | D12: 0 | E12: 1543 | F12: 1931 | G12: 183 | H12: 0 | I12: 0 | J12: 0 | K12: 0 | L12: 0 | M12: 0 | N12: 0 | O12: 0 | P12: 0 | Q12: =SUM(D12:P12) -> 3657 | R12: =sum(H12:I12) -> 0 | S12: =sum(J12:L12) -> 0 | T12: =sum(M12:P12) -> 0 | U12: =sum(D12:G12,R12:T12) -> 3657
B13: 3038 | C13: Kementerian Hukum | D13: 0 | E13: 11 | F13: 148 | G13: 41 | H13: 0 | I13: 0 | J13: 0 | K13: 0 | L13: 0 | M13: 0 | N13: 0 | O13: 0 | P13: 0 | Q13: =SUM(D13:P13) -> 200 | R13: =sum(H13:I13) -> 0 | S13: =sum(J13:L13) -> 0 | T13: =sum(M13:P13) -> 0 | U13: =sum(D13:G13,R13:T13) -> 200
B14: 4002 | C14: Kejaksaan Agung | D14: 0 | E14: 4 | F14: 37 | G14: 22 | H14: 0 | I14: 0 | J14: 0 | K14: 0 | L14: 0 | M14: 0 | N14: 0 | O14: 0 | P14: 0 | Q14: =SUM(D14:P14) -> 63 | R14: =sum(H14:I14) -> 0 | S14: =sum(J14:L14) -> 0 | T14: =sum(M14:P14) -> 0 | U14: =sum(D14:G14,R14:T14) -> 63
B15: 4007 | C15: Mahkamah Agung RI | D15: 0 | E15: 230 | F15: 1458 | G15: 676 | H15: 0 | I15: 0 | J15: 0 | K15: 0 | L15: 0 | M15: 4 | N15: 0 | O15: 0 | P15: 0 | Q15: =SUM(D15:P15) -> 2368 | R15: =sum(H15:I15) -> 0 | S15: =sum(J15:L15) -> 0 | T15: =sum(M15:P15) -> 4 | U15: =sum(D15:G15,R15:T15) -> 2368
B16: 4008 | C16: Badan Pemeriksa Keuangan | D16: 0 | E16: 8 | F16: 186 | G16: 45 | H16: 0 | I16: 0 | J16: 0 | K16: 0 | L16: 0 | M16: 0 | N16: 0 | O16: 0 | P16: 0 | Q16: =SUM(D16:P16) -> 239 | R16: =sum(H16:I16) -> 0 | S16: =sum(J16:L16) -> 0 | T16: =sum(M16:P16) -> 0 | U16: =sum(D16:G16,R16:T16) -> 239
B17: 4016 | C17: Badan Pusat Statistik | D17: 0 | E17: 132 | F17: 999 | G17: 148 | H17: 0 | I17: 0 | J17: 1 | K17: 0 | L17: 4 | M17: 2 | N17: 0 | O17: 0 | P17: 0 | Q17: =SUM(D17:P17) -> 1286 | R17: =sum(H17:I17) -> 0 | S17: =sum(J17:L17) -> 5 | T17: =sum(M17:P17) -> 2 | U17: =sum(D17:G17,R17:T17) -> 1286
B18: 4020 | C18: Kementerian Kependudukan Dan Pembangunan Keluarga/Badan Kependudukan Dan Keluarga Berencana Nasional | D18: 0 | E18: 98 | F18: 447 | G18: 150 | H18: 1 | I18: 4 | J18: 45 | K18: 0 | L18: 282 | M18: 719 | N18: 0 | O18: 0 | P18: 0 | Q18: =SUM(D18:P18) -> 1746 | R18: =sum(H18:I18) -> 5 | S18: =sum(J18:L18) -> 327 | T18: =sum(M18:P18) -> 719 | U18: =sum(D18:G18,R18:T18) -> 1746
B19: 4023 | C19: Badan Pengawasan Keuangan dan Pembangunan | D19: 0 | E19: 15 | F19: 156 | G19: 42 | H19: 0 | I19: 0 | J19: 0 | K19: 0 | L19: 0 | M19: 0 | N19: 0 | O19: 0 | P19: 0 | Q19: =SUM(D19:P19) -> 213 | R19: =sum(H19:I19) -> 0 | S19: =sum(J19:L19) -> 0 | T19: =sum(M19:P19) -> 0 | U19: =sum(D19:G19,R19:T19) -> 213
... B22: 4071 | C22: Badan Karantina Indonesia | D22: 0 | E22: 80 | F22: 254 | G22: 61 | H22: 0 | I22: 0 | J22: 0 | K22: 0 | L22: 0 | M22: 0 | N22: 0 | O22: 0 | P22: 0 | Q22: =SUM(D22:P22) -> 395 | R22: =sum(H22:I22) -> 0 | S22: =sum(J22:L22) -> 0 | T22: =sum(M22:P22) -> 0 | U22: =sum(D22:G22,R22:T22) -> 395
A23: JUMLAH INSTANSI PUSAT | D23: =SUM(D7:D22) -> 53 | E23: =SUM(E7:E22) -> 5446 | F23: =SUM(F7:F22) -> 25218 | G23: =SUM(G7:G22) -> 11216 | H23: =SUM(H7:H22) -> 1 | I23: =SUM(I7:I22) -> 4 | J23: =SUM(J7:J22) -> 46 | K23: =SUM(K7:K22) -> 0 | ... Q23: =SUM(Q7:Q22) -> 44877 | R23: =sum(H23:I23) -> 5 | S23: =sum(J23:L23) -> 1364 | T23: =sum(M23:P23) -> 1575 | U23: =sum(D23:G23,R23:T23) -> 44877
B24: 6100 | C24: Pemerintah Provinsi Jawa Barat | D24: 69 | E24: 2319 | F24: 15838 | G24: 8548 | H24: 5 | I24: 0 | J24: 897 | K24: 0 | L24: 1705 | M24: 22628 | N24: 443 | O24: 19 | P24: 1 | Q24: =SUM(D24:P24) -> 52472 | R24: =sum(H24:I24) -> 5 | S24: =sum(J24:L24) -> 2602 | T24: =sum(M24:P24) -> 23091 | U24: =sum(D24:G24,R24:T24) -> 52472
B25: 6101 | C25: Pemerintah Kab. Bogor | D25: 25 | E25: 1501 | F25: 7564 | G25: 2800 | H25: 30 | I25: 2 | J25: 751 | K25: 0 | L25: 1478 | M25: 11408 | N25: 259 | O25: 44 | P25: 0 | Q25: =SUM(D25:P25) -> 25862 | R25: =sum(H25:I25) -> 32 | S25: =sum(J25:L25) -> 2229 | T25: =sum(M25:P25) -> 11711 | U25: =sum(D25:G25,R25:T25) -> 25862
B26: 6102 | C26: Pemerintah Kab. Sukabumi | D26: 32 | E26: 937 | F26: 4539 | G26: 2429 | H26: 0 | I26: 1 | J26: 119 | K26: 0 | L26: 484 | M26: 4373 | N26: 157 | O26: 0 | P26: 0 | Q26: =SUM(D26:P26) -> 13071 | R26: =sum(H26:I26) -> 1 | S26: =sum(J26:L26) -> 603 | T26: =sum(M26:P26) -> 4530 | U26: =sum(D26:G26,R26:T26) -> 13071
B27: 6103 | C27: Pemerintah Kab. Cianjur | D27: 4 | E27: 469 | F27: 4640 | G27: 2199 | H27: 0 | I27: 0 | J27: 273 | K27: 0 | L27: 707 | M27: 6993 | N27: 150 | O27: 17 | P27: 0 | Q27: =SUM(D27:P27) -> 15452 | R27: =sum(H27:I27) -> 0 | S27: =sum(J27:L27) -> 980 | T27: =sum(M27:P27) -> 7160 | U27: =sum(D27:G27,R27:T27) -> 15452
B28: 6104 | C28: Pemerintah Kab. Bekasi | D28: 17 | E28: 730 | F28: 6282 | G28: 2016 | H28: 455 | I28: 447 | J28: 3142 | K28: 0 | L28: 854 | M28: 8414 | N28: 102 | O28: 0 | P28: 0 | Q28: =SUM(D28:P28) -> 22459 | R28: =sum(H28:I28) -> 902 | S28: =sum(J28:L28) -> 3996 | T28: =sum(M28:P28) -> 8516 | U28: =sum(D28:G28,R28:T28) -> 22459
B29: 6105 | C29: Pemerintah Kab. Karawang | D29: 10 | E29: 738 | F29: 4925 | G29: 2006 | H29: 8 | I29: 17 | J29: 172 | K29: 0 | L29: 972 | M29: 4395 | N29: 170 | O29: 7 | P29: 0 | Q29: =SUM(D29:P29) -> 13420 | R29: =sum(H29:I29) -> 25 | S29: =sum(J29:L29) -> 1144 | T29: =sum(M29:P29) -> 4572 | U29: =sum(D29:G29,R29:T29) -> 13420
B30: 6106 | C30: Pemerintah Kab. Purwakarta | D30: 10 | E30: 717 | F30: 3746 | G30: 1266 | H30: 11 | I30: 0 | J30: 105 | K30: 1 | L30: 400 | M30: 1686 | N30: 64 | O30: 1 | P30: 0 | Q30: =SUM(D30:P30) -> 8007 | R30: =sum(H30:I30) -> 11 | S30: =sum(J30:L30) -> 506 | T30: =sum(M30:P30) -> 1751 | U30: =sum(D30:G30,R30:T30) -> 8007
B31: 6107 | C31: Pemerintah Kab. Subang | D31: 15 | E31: 676 | F31: 5069 | G31: 2369 | H31: 3 | I31: 3 | J31: 126 | K31: 0 | L31: 329 | M31: 3590 | N31: 53 | O31: 0 | P31: 0 | Q31: =SUM(D31:P31) -> 12233 | R31: =sum(H31:I31) -> 6 | S31: =sum(J31:L31) -> 455 | T31: =sum(M31:P31) -> 3643 | U31: =sum(D31:G31,R31:T31) -> 12233
B32: 6108 | C32: Pemerintah Kab. Bandung | D32: 31 | E32: 1385 | F32: 5972 | G32: 2906 | H32: 23 | I32: 0 | J32: 139 | K32: 4 | L32: 628 | M32: 7911 | N32: 153 | O32: 6 | P32: 0 | Q32: =SUM(D32:P32) -> 19158 | R32: =sum(H32:I32) -> 23 | S32: =sum(J32:L32) -> 771 | T32: =sum(M32:P32) -> 8070 | U32: =sum(D32:G32,R32:T32) -> 19158
B33: 6109 | C33: Pemerintah Kab. Sumedang | D33: 4 | E33: 485 | F33: 3743 | G33: 2301 | H33: 2 | I33: 0 | J33: 53 | K33: 0 | L33: 386 | M33: 2935 | N33: 57 | O33: 4 | P33: 0 | Q33: =SUM(D33:P33) -> 9970 | R33: =sum(H33:I33) -> 2 | S33: =sum(J33:L33) -> 439 | T33: =sum(M33:P33) -> 2996 | U33: =sum(D33:G33,R33:T33) -> 9970
B34: 6110 | C34: Pemerintah Kab. Garut | D34: 17 | E34: 874 | F34: 5688 | G34: 3596 | H34: 43 | I34: 28 | J34: 615 | K34: 1 | L34: 2032 | M34: 7054 | N34: 206 | O34: 0 | P34: 0 | Q34: =SUM(D34:P34) -> 20154 | R34: =sum(H34:I34) -> 71 | S34: =sum(J34:L34) -> 2648 | T34: =sum(M34:P34) -> 7260 | U34: =sum(D34:G34,R34:T34) -> 20154
B35: 6111 | C35: Pemerintah Kab. Tasikmalaya | D35: 1 | E35: 411 | F35: 4714 | G35: 2441 | H35: 4 | I35: 3 | J35: 112 | K35: 0 | L35: 861 | M35: 3678 | N35: 186 | O35: 0 | P35: 0 | Q35: =SUM(D35:P35) -> 12411 | R35: =sum(H35:I35) -> 7 | S35: =sum(J35:L35) -> 973 | T35: =sum(M35:P35) -> 3864 | U35: =sum(D35:G35,R35:T35) -> 12411
... B51: 6179 | C51: Pemerintah Kota Banjar | D51: 0 | E51: 305 | F51: 1876 | G51: 430 | H51: 314 | I51: 0 | J51: 754 | K51: 0 | L51: 265 | M51: 786 | N51: 131 | O51: 0 | P51: 0 | Q51: =SUM(D51:P51) -> 4861 | R51: =sum(H51:I51) -> 314 | S51: =sum(J51:L51) -> 1019 | T51: =sum(M51:P51) -> 917 | U51: =sum(D51:G51,R51:T51) -> 4861
B52: JUMLAH SEWILAYAH JAWA BARAT | D52: =SUM(D24:D51) -> 403 | E52: =SUM(E24:E51) -> 21147 | F52: =SUM(F24:F51) -> 130552 | G52: =SUM(G24:G51) -> 58809 | H52: =SUM(H24:H51) -> 1492 | I52: =SUM(I24:I51) -> 959 | J52: =SUM(J24:J51) -> 14856 | K52: =SUM(K24:K51) -> 87 | ... Q52: =SUM(Q24:Q51) -> 378744 | R52: =sum(H52:I52) -> 2451 | S52: =sum(J52:L52) -> 32144 | T52: =sum(M52:P52) -> 133238 | U52: =sum(D52:G52,R52:T52) -> 378744
B53: 6200 | C53: Pemerintah Provinsi Banten | D53: 11 | E53: 439 | F53: 4684 | G53: 3146 | H53: 83 | I53: 8 | J53: 2864 | K53: 0 | L53: 470 | M53: 9834 | N53: 115 | O53: 1 | P53: 0 | Q53: =SUM(D53:P53) -> 21655 | R53: =sum(H53:I53) -> 91 | S53: =sum(J53:L53) -> 3334 | T53: =sum(M53:P53) -> 9950 | U53: =sum(D53:G53,R53:T53) -> 21655
B54: 6201 | C54: Pemerintah Kab. Serang | D54: 38 | E54: 619 | F54: 5078 | G54: 1803 | H54: 21 | I54: 0 | J54: 66 | K54: 0 | L54: 276 | M54: 2212 | N54: 57 | O54: 1 | P54: 0 | Q54: =SUM(D54:P54) -> 10171 | R54: =sum(H54:I54) -> 21 | S54: =sum(J54:L54) -> 342 | T54: =sum(M54:P54) -> 2270 | U54: =sum(D54:G54,R54:T54) -> 10171
B55: 6202 | C55: Pemerintah Kab. Pandeglang | D55: 7 | E55: 607 | F55: 4974 | G55: 1807 | H55: 12 | I55: 6 | J55: 213 | K55: 0 | L55: 347 | M55: 4571 | N55: 91 | O55: 0 | P55: 0 | Q55: =SUM(D55:P55) -> 12635 | R55: =sum(H55:I55) -> 18 | S55: =sum(J55:L55) -> 560 | T55: =sum(M55:P55) -> 4662 | U55: =sum(D55:G55,R55:T55) -> 12635
B56: 6203 | C56: Pemerintah Kab. Lebak | D56: 60 | E56: 685 | F56: 4805 | G56: 1611 | H56: 4 | I56: 13 | J56: 279 | K56: 0 | L56: 888 | M56: 3880 | N56: 157 | O56: 2 | P56: 0 | Q56: =SUM(D56:P56) -> 12384 | R56: =sum(H56:I56) -> 17 | S56: =sum(J56:L56) -> 1167 | T56: =sum(M56:P56) -> 4039 | U56: =sum(D56:G56,R56:T56) -> 12384
B57: 6204 | C57: Pemerintah Kab. Tangerang | D57: 7 | E57: 1346 | F57: 6154 | G57: 1838 | H57: 6 | I57: 3 | J57: 619 | K57: 0 | L57: 426 | M57: 5329 | N57: 122 | O57: 10 | P57: 0 | Q57: =SUM(D57:P57) -> 15860 | R57: =sum(H57:I57) -> 9 | S57: =sum(J57:L57) -> 1045 | T57: =sum(M57:P57) -> 5461 | U57: =sum(D57:G57,R57:T57) -> 15860
B58: 6271 | C58: Pemerintah Kota Tangerang | D58: 19 | E58: 499 | F58: 4261 | G58: 1356 | H58: 107 | I58: 0 | J58: 1479 | K58: 2 | L58: 673 | M58: 4967 | N58: 345 | O58: 22 | P58: 0 | Q58: =SUM(D58:P58) -> 13730 | R58: =sum(H58:I58) -> 107 | S58: =sum(J58:L58) -> 2154 | T58: =sum(M58:P58) -> 5334 | U58: =sum(D58:G58,R58:T58) -> 13730
...

Sheet JENKEL ASN
A1: ASN OKTOBER 2025
A2: berdasarkan Jenis Kelamin ASN
A3: keadaan data pada tanggal : 2 November 2025
A5: JENIS | B5: KODE | C5: INSTANSI | D5: PNS | F5: PPPK | H5: JUMLAH | I5: ASN
D6: PRIA | E6: WANITA | F6: PRIA | G6: WANITA | I6: PRIA | J6: WANITA | K6: %PRIA | L6: %WANITA | M6: JUMLAH
A7: INSTANSI PUSAT | B7: 3003 | C7: Kementerian Pertahanan | D7: 936 | E7: 727 | F7: 185 | G7: 958 | H7: =SUM(D7:G7) -> 2806 | I7: =D7+F7 -> 1121 | J7: =E7+G7 -> 1685 | K7: =I7/H7 -> 0.39950107 | L7: =J7/H7 -> 0.60049893 | M7: =SUM(I7:J7) -> 2806
B8: 3005 | C8: Kementerian Keuangan | D8: 2006 | E8: 1007 | F8: 0 | G8: 0 | H8: =SUM(D8:G8) -> 3013 | I8: =D8+F8 -> 2006 | J8: =E8+G8 -> 1007 | K8: =I8/H8 -> 0.66578161 | L8: =J8/H8 -> 0.33421839 | M8: =SUM(I8:J8) -> 3013
B9: 3006 | C9: Kementerian Pertanian | D9: 928 | E9: 694 | F9: 0 | G9: 0 | H9: =SUM(D9:G9) -> 1622 | I9: =D9+F9 -> 928 | J9: =E9+G9 -> 694 | K9: =I9/H9 -> 0.57213317 | L9: =J9/H9 -> 0.42786683 | M9: =SUM(I9:J9) -> 1622
B10: 3012 | C10: Kementerian Agama | D10: 13213 | E10: 12154 | F10: 383 | G10: 356 | H10: =SUM(D10:G10) -> 26106 | I10: =D10+F10 -> 13596 | J10: =E10+G10 -> 12510 | K10: =I10/H10 -> 0.52079982 | L10: =J10/H10 -> 0.47920018 | M10: =SUM(I10:J10) -> 26106
B11: 3023 | C11: Kementerian Hak Asasi Manusia | D11: 22 | E11: 10 | F11: 0 | G11: 0 | H11: =SUM(D11:G11) -> 32 | I11: =D11+F11 -> 22 | J11: =E11+G11 -> 10 | K11: =I11/H11 -> 0.6875 | L11: =J11/H11 -> 0.3125 | M11: =SUM(I11:J11) -> 32
B12: 3024 | C12: Kementerian Imigrasi dan Pemasyarakatan | D12: 2736 | E12: 921 | F12: 0 | G12: 0 | H12: =SUM(D12:G12) -> 3657 | I12: =D12+F12 -> 2736 | J12: =E12+G12 -> 921 | K12: =I12/H12 -> 0.74815422 | L12: =J12/H12 -> 0.25184578 | M12: =SUM(I12:J12) -> 3657
B13: 3038 | C13: Kementerian Hukum | D13: 98 | E13: 102 | F13: 0 | G13: 0 | H13: =SUM(D13:G13) -> 200 | I13: =D13+F13 -> 98 | J13: =E13+G13 -> 102 | K13: =I13/H13 -> 0.49 | L13: =J13/H13 -> 0.51 | M13: =SUM(I13:J13) -> 200
B14: 4002 | C14: Kejaksaan Agung | D14: 32 | E14: 31 | F14: 0 | G14: 0 | H14: =SUM(D14:G14) -> 63 | I14: =D14+F14 -> 32 | J14: =E14+G14 -> 31 | K14: =I14/H14 -> 0.50793651 | L14: =J14/H14 -> 0.49206349 | M14: =SUM(I14:J14) -> 63
B15: 4007 | C15: Mahkamah Agung RI | D15: 1337 | E15: 1027 | F15: 3 | G15: 1 | H15: =SUM(D15:G15) -> 2368 | I15: =D15+F15 -> 1340 | J15: =E15+G15 -> 1028 | K15: =I15/H15 -> 0.56587838 | L15: =J15/H15 -> 0.43412162 | M15: =SUM(I15:J15) -> 2368
B16: 4008 | C16: Badan Pemeriksa Keuangan | D16: 138 | E16: 101 | F16: 0 | G16: 0
B17: 4016 | C17: Badan Pusat Statistik | D17: 739 | E17: 540 | F17: 5 | G17: 2 | H17: =SUM(D17:G17) -> 1286 | I17: =D17+F17 -> 744 | J17: =E17+G17 -> 542 | K17: =I17/H17 -> 0.5785381 | L17: =J17/H17 -> 0.4214619 | M17: =SUM(I17:J17) -> 1286
B18: 4020 | C18: Kementerian Kependudukan Dan Pembangunan Keluarga/Badan Kependudukan Dan Keluarga Berencana Nasional | D18: 295 | E18: 400 | F18: 374 | G18: 677 | H18: =SUM(D18:G18) -> 1746 | I18: =D18+F18 -> 669 | J18: =E18+G18 -> 1077 | K18: =I18/H18 -> 0.38316151 | L18: =J18/H18 -> 0.61683849 | M18: =SUM(I18:J18) -> 1746
B19: 4023 | C19: Badan Pengawasan Keuangan dan Pembangunan | D19: 118 | E19: 95 | F19: 0 | G19: 0 | H19: =SUM(D19:G19) -> 213 | I19: =D19+F19 -> 118 | J19: =E19+G19 -> 95 | K19: =I19/H19 -> 0.55399061 | L19: =J19/H19 -> 0.44600939 | M19: =SUM(I19:J19) -> 213
B20: 4024 | C20: Kementerian Agraria dan Tata Ruang/Badan Pertanahan Nasional | D20: 142 | E20: 64 | F20: 0 | G20: 0 | H20: =SUM(D20:G20) -> 206 | I20: =D20+F20 -> 142 | J20: =E20+G20 -> 64 | K20: =I20/H20 -> 0.68932039 | L20: =J20/H20 -> 0.31067961 | M20: =SUM(I20:J20) -> 206
B21: 4033 | C21: Kepolisian Negara | D21: 501 | E21: 424 | F21: 0 | G21: 0 | H21: =SUM(D21:G21) -> 925 | I21: =D21+F21 -> 501 | J21: =E21+G21 -> 424 | K21: =I21/H21 -> 0.54162162 | L21: =J21/H21 -> 0.45837838 | M21: =SUM(I21:J21) -> 925
B22: 4071 | C22: Badan Karantina Indonesia | D22: 233 | E22: 162 | F22: 0 | G22: 0 | H22: =SUM(D22:G22) -> 395 | I22: =D22+F22 -> 233 | J22: =E22+G22 -> 162 | K22: =I22/H22 -> 0.58987342 | L22: =J22/H22 -> 0.41012658 | M22: =SUM(I22:J22) -> 395
A23: JUMLAH INSTANSI PUSAT | D23: =SUM(D7:D22) -> 23474 | E23: =SUM(E7:E22) -> 18459 | F23: =SUM(F7:F22) -> 950 | G23: =SUM(G7:G22) -> 1994 | H23: =SUM(H7:H22) -> 44638 | I23: =D23+F23 -> 24424 | J23: =E23+G23 -> 20453 | K23: =I23/H23 -> 0.54715713 | L23: =J23/H23 -> 0.45819705 | M23: =SUM(I23:J23) -> 44877
A24: INSTANSI DAERAH | B24: 6100 | C24: Pemerintah Provinsi Jawa Barat | D24: 13605 | E24: 13169 | F24: 12078 | G24: 13620 | H24: =SUM(D24:G24) -> 52472 | I24: =D24+F24 -> 25683 | J24: =E24+G24 -> 26789 | K24: =I24/H24 -> 0.48946105 | L24: =J24/H24 -> 0.51053895 | M24: =SUM(I24:J24) -> 52472
B25: 6101 | C25: Pemerintah Kab. Bogor | D25: 5137 | E25: 6753 | F25: 4657 | G25: 9315 | H25: =SUM(D25:G25) -> 25862 | I25: =D25+F25 -> 9794 | J25: =E25+G25 -> 16068 | K25: =I25/H25 -> 0.37870234 | L25: =J25/H25 -> 0.62129766 | M25: =SUM(I25:J25) -> 25862
B26: 6102 | C26: Pemerintah Kab. Sukabumi | D26: 4244 | E26: 3693 | F26: 2234 | G26: 2900 | H26: =SUM(D26:G26) -> 13071 | I26: =D26+F26 -> 6478 | J26: =E26+G26 -> 6593 | K26: =I26/H26 -> 0.49560095 | L26: =J26/H26 -> 0.50439905 | M26: =SUM(I26:J26) -> 13071
B27: 6103 | C27: Pemerintah Kab. Cianjur | D27: 3477 | E27: 3835 | F27: 3415 | G27: 4725 | H27: =SUM(D27:G27) -> 15452 | I27: =D27+F27 -> 6892 | J27: =E27+G27 -> 8560 | K27: =I27/H27 -> 0.4460264 | L27: =J27/H27 -> 0.5539736 | M27: =SUM(I27:J27) -> 15452
B28: 6104 | C28: Pemerintah Kab. Bekasi | D28: 3505 | E28: 5540 | F28: 6455 | G28: 6959 | H28: =SUM(D28:G28) -> 22459 | I28: =D28+F28 -> 9960 | J28: =E28+G28 -> 12499 | K28: =I28/H28 -> 0.44347478 | L28: =J28/H28 -> 0.55652522 | M28: =SUM(I28:J28) -> 22459
B29: 6105 | C29: Pemerintah Kab. Karawang | D29: 3293 | E29: 4386 | F29: 2141 | G29: 3600 | H29: =SUM(D29:G29) -> 13420 | I29: =D29+F29 -> 5434 | J29: =E29+G29 -> 7986 | K29: =I29/H29 -> 0.40491803 | L29: =J29/H29 -> 0.59508197 | M29: =SUM(I29:J29) -> 13420
B30: 6106 | C30: Pemerintah Kab. Purwakarta | D30: 2550 | E30: 3189 | F30: 719 | G30: 1549 | H30: =SUM(D30:G30) -> 8007 | I30: =D30+F30 -> 3269 | J30: =E30+G30 -> 4738 | K30: =I30/H30 -> 0.40826777 | L30: =J30/H30 -> 0.59173223 | M30: =SUM(I30:J30) -> 8007
B31: 6107 | C31: Pemerintah Kab. Subang | D31: 3756 | E31: 4373 | F31: 1377 | G31: 2727 | H31: =SUM(D31:G31) -> 12233 | I31: =D31+F31 -> 5133 | J31: =E31+G31 -> 7100 | K31: =I31/H31 -> 0.41960271 | L31: =J31/H31 -> 0.58039729 | M31: =SUM(I31:J31) -> 12233
B32: 6108 | C32: Pemerintah Kab. Bandung | D32: 4236 | E32: 6058 | F32: 2784 | G32: 6080 | H32: =SUM(D32:G32) -> 19158 | I32: =D32+F32 -> 7020 | J32: =E32+G32 -> 12138 | K32: =I32/H32 -> 0.36642656 | L32: =J32/H32 -> 0.63357344 | M32: =SUM(I32:J32) -> 19158
B33: 6109 | C33: Pemerintah Kab. Sumedang | D33: 2744 | E33: 3789 | F33: 1066 | G33: 2371 | H33: =SUM(D33:G33) -> 9970 | I33: =D33+F33 -> 3810 | J33: =E33+G33 -> 6160 | K33: =I33/H33 -> 0.38214644 | L33: =J33/H33 -> 0.61785356 | M33: =SUM(I33:J33) -> 9970
B34: 6110 | C34: Pemerintah Kab. Garut | D34: 4794 | E34: 5381 | F34: 3674 | G34: 6305 | H34: =SUM(D34:G34) -> 20154 | I34: =D34+F34 -> 8468 | J34: =E34+G34 -> 11686 | K34: =I34/H34 -> 0.42016473 | L34: =J34/H34 -> 0.57983527 | M34: =SUM(I34:J34) -> 20154
B35: 6111 | C35: Pemerintah Kab. Tasikmalaya | D35: 3093 | E35: 4474 | F35: 1636 | G35: 3208 | H35: =SUM(D35:G35) -> 12411 | I35: =D35+F35 -> 4729 | J35: =E35+G35 -> 7682 | K35: =I35/H35 -> 0.38103295 | L35: =J35/H35 -> 0.61896705 | M35: =SUM(I35:J35) -> 12411
B36: 6112 | C36: Pemerintah Kab. Ciamis | D36: 2513 | E36: 3337 | F36: 1332 | G36: 2690 | H36: =SUM(D36:G36) -> 9872 | I36: =D36+F36 -> 3845 | J36: =E36+G36 -> 6027 | K36: =I36/H36 -> 0.38948541 | L36: =J36/H36 -> 0.61051459 | M36: =SUM(I36:J36) -> 9872
... B51: 6179 | C51: Pemerintah Kota Banjar | D51: 1184 | E51: 1427 | F51: 1245 | G51: 1005 | H51: =SUM(D51:G51) -> 4861 | I51: =D51+F51 -> 2429 | J51: =E51+G51 -> 2432 | K51: =I51/H51 -> 0.49969142 | L51: =J51/H51 -> 0.50030858 | M51: =SUM(I51:J51) -> 4861
B52: JUMLAH SEWILAYAH JAWA BARAT | D52: =SUM(D24:D51) -> 94290 | E52: =SUM(E24:E51) -> 116621 | F52: =SUM(F24:F51) -> 67446 | G52: =SUM(G24:G51) -> 100387 | H52: =SUM(H24:H51) -> 378744 | I52: =D52+F52 -> 161736 | J52: =E52+G52 -> 217008 | K52: =I52/H52 -> 0.42703251 | L52: =J52/H52 -> 0.57296749 | M52: =SUM(I52:J52) -> 378744
B53: 6200 | C53: Pemerintah Provinsi Banten | D53: 4238 | E53: 4042 | F53: 7205 | G53: 6170 | H53: =SUM(D53:G53) -> 21655 | I53: =D53+F53 -> 11443 | J53: =E53+G53 -> 10212 | K53: =I53/H53 -> 0.528423 | L53: =J53/H53 -> 0.471577 | M53: =SUM(I53:J53) -> 21655
B54: 6201 | C54: Pemerintah Kab. Serang | D54: 3179 | E54: 4359 | F54: 846 | G54: 1787 | H54: =SUM(D54:G54) -> 10171 | I54: =D54+F54 -> 4025 | J54: =E54+G54 -> 6146 | K54: =I54/H54 -> 0.39573297 | L54: =J54/H54 -> 0.60426703 | M54: =SUM(I54:J54) -> 10171
B55: 6202 | C55: Pemerintah Kab. Pandeglang | D55: 3283 | E55: 4112 | F55: 1975 | G55: 3265 | H55: =SUM(D55:G55) -> 12635 | I55: =D55+F55 -> 5258 | J55: =E55+G55 -> 7377 | K55: =I55/H55 -> 0.41614563 | L55: =J55/H55 -> 0.58385437 | M55: =SUM(I55:J55) -> 12635
...

Sheet PENDIDIKAN ASN
A1: ASN OKTOBER 2025
A2: berdasarkan Pendidikan ASN
A3: keadaan data pada tanggal : 2 November 2025
A5: JENIS | B5: KODE | C5: INSTANSI | D5: PNS | M5: PPPK | V5: Jumlah | W5: ASN
D6: SD | E6: SMP | F6: SMA | G6: Diploma I | H6: Diploma II | I6: Diploma III | J6: S1 | K6: S2 | L6: S3 | M6: SD | N6: SMP | O6: SMA | P6: Diploma I | Q6: Diploma II | R6: Diploma III | S6: S1 | T6: S2 | U6: S3 | W6: SD | X6: SMP | Y6: SMA | Z6: Diploma I | AA6: Diploma II | AB6: Diploma III | AC6: S1 | AD6: S2 | AE6: S3 | AF6: JML
A7: INSTANSI PUSAT | B7: 3003 | C7: Kementerian Pertahanan | D7: 9 | E7: 60 | F7: 1109 | G7: 12 | H7: 2 | I7: 132 | J7: 302 | K7: 35 | L7: 2 | M7: 0 | N7: 0 | O7: 0 | P7: 0 | Q7: 0 | R7: 1032 | S7: 17 | T7: 94 | U7: 0 | V7: =SUM(D7:U7) -> 2806 | W7: =D7+M7 -> 9 | X7: =E7+N7 -> 60 | Y7: =F7+O7 -> 1109 | Z7: =G7+P7 -> 12 | AA7: =H7+Q7 -> 2 | AB7: =I7+R7 -> 1164 | AC7: =J7+S7 -> 319 | AD7: =K7+T7 -> 129 | AE7: =L7+U7 -> 2 | AF7: =SUM(W7:AE7) -> 2806
B8: 3005 | C8: Kementerian Keuangan | D8: 2 | E8: 0 | F8: 74 | G8: 674 | H8: 1 | I8: 750 | J8: 1111 | K8: 386 | L8: 15 | M8: 0 | N8: 0 | O8: 0 | P8: 0 | Q8: 0 | R8: 0 | S8: 0 | T8: 0 | U8: 0 | V8: =SUM(D8:U8) -> 3013 | W8: =D8+M8 -> 2 | X8: =E8+N8 -> 0 | Y8: =F8+O8 -> 74 | Z8: =G8+P8 -> 674 | AA8: =H8+Q8 -> 1 | AB8: =I8+R8 -> 750 | AC8: =J8+S8 -> 1111 | AD8: =K8+T8 -> 386 | AE8: =L8+U8 -> 15 | AF8: =SUM(W8:AE8) -> 3013
B9: 3006 | C9: Kementerian Pertanian | D9: 18 | E9: 25 | F9: 447 | G9: 0 | H9: 2 | I9: 197 | J9: 454 | K9: 390 | L9: 89 | M9: 0 | N9: 0 | O9: 0 | P9: 0 | Q9: 0 | R9: 0 | S9: 0 | T9: 0 | U9: 0 | V9: =SUM(D9:U9) -> 1622 | W9: =D9+M9 -> 18 | X9: =E9+N9 -> 25 | Y9: =F9+O9 -> 447 | Z9: =G9+P9 -> 0 | AA9: =H9+Q9 -> 2 | AB9: =I9+R9 -> 197 | AC9: =J9+S9 -> 454 | AD9: =K9+T9 -> 390 | AE9: =L9+U9 -> 89 | AF9: =SUM(W9:AE9) -> 1622
B10: 3012 | C10: Kementerian Agama | D10: 20 | E10: 62 | F10: 906 | G10: 4 | H10: 211 | I10: 80 | J10: 18400 | K10: 4900 | L10: 784 | M10: 0 | N10: 0 | O10: 0 | P10: 0 | Q10: 0 | R10: 0 | S10: 717 | T10: 22 | U10: 0 | V10: =SUM(D10:U10) -> 26106 | W10: =D10+M10 -> 20 | X10: =E10+N10 -> 62 | Y10: =F10+O10 -> 906 | Z10: =G10+P10 -> 4 | AA10: =H10+Q10 -> 211 | AB10: =I10+R10 -> 80 | AC10: =J10+S10 -> 19117 | AD10: =K10+T10 -> 4922 | AE10: =L10+U10 -> 784 | AF10: =SUM(W10:AE10) -> 26106
B11: 3023 | C11: Kementerian Hak Asasi Manusia | D11: 0 | E11: 0 | F11: 3 | G11: 0 | H11: 0 | I11: 2 | J11: 22 | K11: 5 | L11: 0 | M11: 0 | N11: 0 | O11: 0 | P11: 0 | Q11: 0 | R11: 0 | S11: 0 | T11: 0 | U11: 0 | V11: =SUM(D11:U11) -> 32 | W11: =D11+M11 -> 0 | X11: =E11+N11 -> 0 | Y11: =F11+O11 -> 3 | Z11: =G11+P11 -> 0 | AA11: =H11+Q11 -> 0 | AB11: =I11+R11 -> 2 | AC11: =J11+S11 -> 22 | AD11: =K11+T11 -> 5 | AE11: =L11+U11 -> 0 | AF11: =SUM(W11:AE11) -> 32
B12: 3024 | C12: Kementerian Imigrasi dan Pemasyarakatan | D12: 6 | E12: 1 | F12: 1776 | G12: 2 | H12: 0 | I12: 100 | J12: 1386 | K12: 382 | L12: 4 | M12: 0 | N12: 0 | O12: 0 | P12: 0 | Q12: 0 | R12: 0 | S12: 0 | T12: 0 | U12: 0 | V12: =SUM(D12:U12) -> 3657 | W12: =D12+M12 -> 6 | X12: =E12+N12 -> 1 | Y12: =F12+O12 -> 1776 | Z12: =G12+P12 -> 2 | AA12: =H12+Q12 -> 0 | AB12: =I12+R12 -> 100 | AC12: =J12+S12 -> 1386 | AD12: =K12+T12 -> 382 | AE12: =L12+U12 -> 4 | AF12: =SUM(W12:AE12) -> 3657
B13: 3038 | C13: Kementerian Hukum | D13: 0 | E13: 0 | F13: 18 | G13: 0 | H13: 0 | I13: 6 | J13: 111 | K13: 64 | L13: 1 | M13: 0 | N13: 0 | O13: 0 | P13: 0 | Q13: 0 | R13: 0 | S13: 0 | T13: 0 | U13: 0 | V13: =SUM(D13:U13) -> 200 | W13: =D13+M13 -> 0 | X13: =E13+N13 -> 0 | Y13: =F13+O13 -> 18 | Z13: =G13+P13 -> 0 | AA13: =H13+Q13 -> 0 | AB13: =I13+R13 -> 6 | AC13: =J13+S13 -> 111 | AD13: =K13+T13 -> 64 | AE13: =L13+U13 -> 1 | AF13: =SUM(W13:AE13) -> 200
B14: 4002 | C14: Kejaksaan Agung | D14: 0 | E14: 0 | F14: 10 | G14: 0 | H14: 0 | I14: 4 | J14: 32 | K14: 17 | L14: 0 | M14: 0 | N14: 0 | O14: 0 | P14: 0 | Q14: 0 | R14: 0 | S14: 0 | T14: 0 | U14: 0 | V14: =SUM(D14:U14) -> 63 | W14: =D14+M14 -> 0 | X14: =E14+N14 -> 0 | Y14: =F14+O14 -> 10 | Z14: =G14+P14 -> 0 | AA14: =H14+Q14 -> 0 | AB14: =I14+R14 -> 4 | AC14: =J14+S14 -> 32 | AD14: =K14+T14 -> 17 | AE14: =L14+U14 -> 0 | AF14: =SUM(W14:AE14) -> 63
B15: 4007 | C15: Mahkamah Agung RI | D15: 3 | E15: 0 | F15: 161 | G15: 0 | H15: 0 | I15: 235 | J15: 1273 | K15: 650 | L15: 42 | M15: 0 | N15: 0 | O15: 0 | P15: 0 | Q15: 0 | R15: 0 | S15: 4 | T15: 0 | U15: 0 | V15: =SUM(D15:U15) -> 2368 | W15: =D15+M15 -> 3 | X15: =E15+N15 -> 0 | Y15: =F15+O15 -> 161 | Z15: =G15+P15 -> 0 | AA15: =H15+Q15 -> 0 | AB15: =I15+R15 -> 235 | AC15: =J15+S15 -> 1277 | AD15: =K15+T15 -> 650 | AE15: =L15+U15 -> 42 | AF15: =SUM(W15:AE15) -> 2368
B16: 4008 | C16: Badan Pemeriksa Keuangan | D16: 0 | E16: 0 | F16: 6 | G16: 0 | H16: 0 | I16: 12 | J16: 116 | K16: 104 | L16: 1 | M16: 0 | N16: 0 | O16: 0 | P16: 0 | Q16: 0 | R16: 0 | S16: 0 | T16: 0 | U16: 0 | V16: =SUM(D16:U16) -> 239 | W16: =D16+M16 -> 0 | X16: =E16+N16 -> 0 | Y16: =F16+O16 -> 6 | Z16: =G16+P16 -> 0 | AA16: =H16+Q16 -> 0 | AB16: =I16+R16 -> 12 | AC16: =J16+S16 -> 116 | AD16: =K16+T16 -> 104 | AE16: =L16+U16 -> 1 | AF16: =SUM(W16:AE16) -> 239
B17: 4016 | C17: Badan Pusat Statistik | D17: 1 | E17: 2 | F17: 192 | G17: 7 | H17: 0 | I17: 152 | J17: 621 | K17: 301 | L17: 3 | M17: 0 | N17: 0 | O17: 1 | P17: 0 | Q17: 0 | R17: 4 | S17: 2 | T17: 0 | U17: 0 | V17: =SUM(D17:U17) -> 1286 | W17: =D17+M17 -> 1 | X17: =E17+N17 -> 2 | Y17: =F17+O17 -> 193 | Z17: =G17+P17 -> 7 | AA17: =H17+Q17 -> 0 | AB17: =I17+R17 -> 156 | AC17: =J17+S17 -> 623 | AD17: =K17+T17 -> 301 | AE17: =L17+U17 -> 3 | AF17: =SUM(W17:AE17) -> 1286
B18: 4020 | C18: Kementerian Kependudukan Dan Pembangunan Keluarga/Badan Kependudukan Dan Keluarga Berencana Nasional | D18: 0 | E18: 0 | F18: 148 | G18: 5 | H18: 1 | I18: 47 | J18: 433 | K18: 60 | L18: 1 | M18: 1 | N18: 4 | O18: 45 | P18: 0 | Q18: 0 | R18: 282 | S18: 719 | T18: 0 | U18: 0 | V18: =SUM(D18:U18) -> 1746 | W18: =D18+M18 -> 1 | X18: =E18+N18 -> 4 | Y18: =F18+O18 -> 193 | Z18: =G18+P18 -> 5 | AA18: =H18+Q18 -> 1 | AB18: =I18+R18 -> 329 | AC18: =J18+S18 -> 1152 | AD18: =K18+T18 -> 60 | AE18: =L18+U18 -> 1 | AF18: =SUM(W18:AE18) -> 1746
B19: 4023 | C19: Badan Pengawasan Keuangan dan Pembangunan | D19: 0 | E19: 0 | F19: 20 | G19: 1 | H19: 0 | I19: 48 | J19: 109 | K19: 34 | L19: 1 | M19: 0 | N19: 0 | O19: 0 | P19: 0 | Q19: 0 | R19: 0 | S19: 0 | T19: 0 | U19: 0 | V19: =SUM(D19:U19) -> 213 | W19: =D19+M19 -> 0 | X19: =E19+N19 -> 0 | Y19: =F19+O19 -> 20 | Z19: =G19+P19 -> 1 | AA19: =H19+Q19 -> 0 | AB19: =I19+R19 -> 48 | AC19: =J19+S19 -> 109 | AD19: =K19+T19 -> 34 | AE19: =L19+U19 -> 1 | AF19: =SUM(W19:AE19) -> 213
... B22: 4071 | C22: Badan Karantina Indonesia | D22: 0 | E22: 3 | F22: 100 | G22: 0 | H22: 3 | I22: 81 | J22: 112 | K22: 90 | L22: 6 | M22: 0 | N22: 0 | O22: 0 | P22: 0 | Q22: 0 | R22: 0 | S22: 0 | T22: 0 | U22: 0 | V22: =SUM(D22:U22) -> 395 | W22: =D22+M22 -> 0 | X22: =E22+N22 -> 3 | Y22: =F22+O22 -> 100 | Z22: =G22+P22 -> 0 | AA22: =H22+Q22 -> 3 | AB22: =I22+R22 -> 81 | AC22: =J22+S22 -> 112 | AD22: =K22+T22 -> 90 | AE22: =L22+U22 -> 6 | AF22: =SUM(W22:AE22) -> 395
A23: JUMLAH INSTANSI PUSAT | D23: =SUM(D7:D22) -> 70 | E23: =SUM(E7:E22) -> 173 | F23: =SUM(F7:F22) -> 5567 | G23: =SUM(G7:G22) -> 717 | H23: =SUM(H7:H22) -> 220 | I23: =SUM(I7:I22) -> 2023 | J23: =SUM(J7:J22) -> 24700 | K23: =SUM(K7:K22) -> 7511 | ... V23: =SUM(V7:V22) -> 44877 | W23: =D23+M23 -> 71 | X23: =E23+N23 -> 177 | Y23: =F23+O23 -> 5613 | Z23: =G23+P23 -> 717 | AA23: =H23+Q23 -> 220 | AB23: =I23+R23 -> 3341 | AC23: =J23+S23 -> 26159 | AD23: =K23+T23 -> 7627 | AE23: =L23+U23 -> 952 | AF23: =SUM(W23:AE23) -> 44877
A24: INSTANSI DAERAH | B24: 6100 | C24: Pemerintah Provinsi Jawa Barat | D24: 81 | E24: 174 | F24: 2038 | G24: 10 | H24: 25 | I24: 1384 | J24: 16968 | K24: 5931 | L24: 163 | M24: 0 | N24: 0 | O24: 897 | P24: 0 | Q24: 0 | R24: 1705 | S24: 22631 | T24: 465 | U24: 0 | V24: =SUM(D24:U24) -> 52472 | W24: =D24+M24 -> 81 | X24: =E24+N24 -> 174 | Y24: =F24+O24 -> 2935 | Z24: =G24+P24 -> 10 | AA24: =H24+Q24 -> 25 | AB24: =I24+R24 -> 3089 | AC24: =J24+S24 -> 39599 | AD24: =K24+T24 -> 6396 | AE24: =L24+U24 -> 163 | AF24: =SUM(W24:AE24) -> 52472
B25: 6101 | C25: Pemerintah Kab. Bogor | D25: 20 | E25: 64 | F25: 1161 | G25: 17 | H25: 48 | I25: 1403 | J25: 7240 | K25: 1917 | L25: 20 | M25: 29 | N25: 2 | O25: 751 | P25: 0 | Q25: 0 | R25: 1478 | S25: 11405 | T25: 307 | U25: 0 | V25: =SUM(D25:U25) -> 25862 | W25: =D25+M25 -> 49 | X25: =E25+N25 -> 66 | Y25: =F25+O25 -> 1912 | Z25: =G25+P25 -> 17 | AA25: =H25+Q25 -> 48 | AB25: =I25+R25 -> 2881 | AC25: =J25+S25 -> 18645 | AD25: =K25+T25 -> 2224 | AE25: =L25+U25 -> 20 | AF25: =SUM(W25:AE25) -> 25862
B26: 6102 | C26: Pemerintah Kab. Sukabumi | D26: 39 | E26: 61 | F26: 734 | G26: 8 | H26: 75 | I26: 795 | J26: 5102 | K26: 1110 | L26: 13 | M26: 0 | N26: 1 | O26: 119 | P26: 0 | Q26: 0 | R26: 483 | S26: 4371 | T26: 160 | U26: 0 | V26: =SUM(D26:U26) -> 13071 | W26: =D26+M26 -> 39 | X26: =E26+N26 -> 62 | Y26: =F26+O26 -> 853 | Z26: =G26+P26 -> 8 | AA26: =H26+Q26 -> 75 | AB26: =I26+R26 -> 1278 | AC26: =J26+S26 -> 9473 | AD26: =K26+T26 -> 1270 | AE26: =L26+U26 -> 13 | AF26: =SUM(W26:AE26) -> 13071
B27: 6103 | C27: Pemerintah Kab. Cianjur | D27: 17 | E27: 34 | F27: 372 | G27: 7 | H27: 72 | I27: 585 | J27: 5183 | K27: 1033 | L27: 9 | M27: 0 | N27: 0 | O27: 273 | P27: 0 | Q27: 2 | R27: 705 | S27: 6993 | T27: 167 | U27: 0 | V27: =SUM(D27:U27) -> 15452 | W27: =D27+M27 -> 17 | X27: =E27+N27 -> 34 | Y27: =F27+O27 -> 645 | Z27: =G27+P27 -> 7 | AA27: =H27+Q27 -> 74 | AB27: =I27+R27 -> 1290 | AC27: =J27+S27 -> 12176 | AD27: =K27+T27 -> 1200 | AE27: =L27+U27 -> 9 | AF27: =SUM(W27:AE27) -> 15452
B28: 6104 | C28: Pemerintah Kab. Bekasi | D28: 59 | E28: 58 | F28: 498 | G28: 3 | H28: 63 | I28: 556 | J28: 6309 | K28: 1483 | L28: 16 | M28: 455 | N28: 447 | O28: 3135 | P28: 0 | Q28: 0 | R28: 836 | S28: 8443 | T28: 98 | U28: 0 | V28: =SUM(D28:U28) -> 22459 | W28: =D28+M28 -> 514 | X28: =E28+N28 -> 505 | Y28: =F28+O28 -> 3633 | Z28: =G28+P28 -> 3 | AA28: =H28+Q28 -> 63 | AB28: =I28+R28 -> 1392 | AC28: =J28+S28 -> 14752 | AD28: =K28+T28 -> 1581 | AE28: =L28+U28 -> 16 | AF28: =SUM(W28:AE28) -> 22459
B29: 6105 | C29: Pemerintah Kab. Karawang | D29: 8 | E29: 38 | F29: 619 | G29: 11 | H29: 79 | I29: 961 | J29: 5105 | K29: 849 | L29: 9 | M29: 8 | N29: 17 | O29: 172 | P29: 0 | Q29: 0 | R29: 971 | S29: 4399 | T29: 174 | U29: 0 | V29: =SUM(D29:U29) -> 13420 | W29: =D29+M29 -> 16 | X29: =E29+N29 -> 55 | Y29: =F29+O29 -> 791 | Z29: =G29+P29 -> 11 | AA29: =H29+Q29 -> 79 | AB29: =I29+R29 -> 1932 | AC29: =J29+S29 -> 9504 | AD29: =K29+T29 -> 1023 | AE29: =L29+U29 -> 9 | AF29: =SUM(W29:AE29) -> 13420
B30: 6106 | C30: Pemerintah Kab. Purwakarta | D30: 42 | E30: 63 | F30: 786 | G30: 16 | H30: 56 | I30: 583 | J30: 3589 | K30: 596 | L30: 8 | M30: 11 | N30: 0 | O30: 105 | P30: 0 | Q30: 1 | R30: 377 | S30: 1707 | T30: 67 | U30: 0 | V30: =SUM(D30:U30) -> 8007 | W30: =D30+M30 -> 53 | X30: =E30+N30 -> 63 | Y30: =F30+O30 -> 891 | Z30: =G30+P30 -> 16 | AA30: =H30+Q30 -> 57 | AB30: =I30+R30 -> 960 | AC30: =J30+S30 -> 5296 | AD30: =K30+T30 -> 663 | AE30: =L30+U30 -> 8 | AF30: =SUM(W30:AE30) -> 8007
B31: 6107 | C31: Pemerintah Kab. Subang | D31: 26 | E31: 16 | F31: 713 | G31: 8 | H31: 52 | I31: 621 | J31: 5734 | K31: 952 | L31: 7 | M31: 3 | N31: 3 | O31: 126 | P31: 0 | Q31: 0 | R31: 328 | S31: 3589 | T31: 55 | U31: 0 | V31: =SUM(D31:U31) -> 12233 | W31: =D31+M31 -> 29 | X31: =E31+N31 -> 19 | Y31: =F31+O31 -> 839 | Z31: =G31+P31 -> 8 | AA31: =H31+Q31 -> 52 | AB31: =I31+R31 -> 949 | AC31: =J31+S31 -> 9323 | AD31: =K31+T31 -> 1007 | AE31: =L31+U31 -> 7 | AF31: =SUM(W31:AE31) -> 12233
B32: 6108 | C32: Pemerintah Kab. Bandung | D32: 73 | E32: 122 | F32: 1130 | G32: 17 | H32: 236 | I32: 1339 | J32: 6188 | K32: 1168 | L32: 20 | M32: 23 | N32: 0 | O32: 139 | P32: 0 | Q32: 4 | R32: 628 | S32: 7922 | T32: 149 | U32: 0 | V32: =SUM(D32:U32) -> 19158 | W32: =D32+M32 -> 96 | X32: =E32+N32 -> 122 | Y32: =F32+O32 -> 1269 | Z32: =G32+P32 -> 17 | AA32: =H32+Q32 -> 240 | AB32: =I32+R32 -> 1967 | AC32: =J32+S32 -> 14110 | AD32: =K32+T32 -> 1317 | AE32: =L32+U32 -> 20 | AF32: =SUM(W32:AE32) -> 19158
B33: 6109 | C33: Pemerintah Kab. Sumedang | D33: 13 | E33: 55 | F33: 569 | G33: 5 | H33: 31 | I33: 598 | J33: 4515 | K33: 736 | L33: 11 | M33: 2 | N33: 0 | O33: 53 | P33: 0 | Q33: 0 | R33: 379 | S33: 2933 | T33: 70 | U33: 0 | V33: =SUM(D33:U33) -> 9970 | W33: =D33+M33 -> 15 | X33: =E33+N33 -> 55 | Y33: =F33+O33 -> 622 | Z33: =G33+P33 -> 5 | AA33: =H33+Q33 -> 31 | AB33: =I33+R33 -> 977 | AC33: =J33+S33 -> 7448 | AD33: =K33+T33 -> 806 | AE33: =L33+U33 -> 11 | AF33: =SUM(W33:AE33) -> 9970
B34: 6110 | C34: Pemerintah Kab. Garut | D34: 27 | E34: 59 | F34: 855 | G34: 3 | H34: 84 | I34: 672 | J34: 7229 | K34: 1231 | L34: 15 | M34: 43 | N34: 28 | O34: 615 | P34: 0 | Q34: 2 | R34: 2029 | S34: 7069 | T34: 193 | U34: 0 | V34: =SUM(D34:U34) -> 20154 | W34: =D34+M34 -> 70 | X34: =E34+N34 -> 87 | Y34: =F34+O34 -> 1470 | Z34: =G34+P34 -> 3 | AA34: =H34+Q34 -> 86 | AB34: =I34+R34 -> 2701 | AC34: =J34+S34 -> 14298 | AD34: =K34+T34 -> 1424 | AE34: =L34+U34 -> 15 | AF34: =SUM(W34:AE34) -> 20154
B35: 6111 | C35: Pemerintah Kab. Tasikmalaya | D35: 8 | E35: 14 | F35: 261 | G35: 1 | H35: 22 | I35: 601 | J35: 5683 | K35: 968 | L35: 9 | M35: 4 | N35: 3 | O35: 81 | P35: 0 | Q35: 0 | R35: 844 | S35: 3731 | T35: 181 | U35: 0 | V35: =SUM(D35:U35) -> 12411 | W35: =D35+M35 -> 12 | X35: =E35+N35 -> 17 | Y35: =F35+O35 -> 342 | Z35: =G35+P35 -> 1 | AA35: =H35+Q35 -> 22 | AB35: =I35+R35 -> 1445 | AC35: =J35+S35 -> 9414 | AD35: =K35+T35 -> 1149 | AE35: =L35+U35 -> 9 | AF35: =SUM(W35:AE35) -> 12411
B36: 6112 | C36: Pemerintah Kab. Ciamis | D36: 11 | E36: 37 | F36: 448 | G36: 4 | H36: 58 | I36: 638 | J36: 3987 | K36: 651 | L36: 16 | M36: 1 | N36: 0 | O36: 106 | P36: 0 | Q36: 0 | R36: 416 | S36: 3356 | T36: 143 | U36: 0 | V36: =SUM(D36:U36) -> 9872 | W36: =D36+M36 -> 12 | X36: =E36+N36 -> 37 | Y36: =F36+O36 -> 554 | Z36: =G36+P36 -> 4 | AA36: =H36+Q36 -> 58 | AB36: =I36+R36 -> 1054 | AC36: =J36+S36 -> 7343 | AD36: =K36+T36 -> 794 | AE36: =L36+U36 -> 16 | AF36: =SUM(W36:AE36) -> 9872
... B51: 6179 | C51: Pemerintah Kota Banjar | D51: 1 | E51: 6 | F51: 272 | G51: 1 | H51: 5 | I51: 364 | J51: 1560 | K51: 396 | L51: 6 | M51: 314 | N51: 0 | O51: 754 | P51: 0 | Q51: 0 | R51: 265 | S51: 798 | T51: 119 | U51: 0 | V51: =SUM(D51:U51) -> 4861 | W51: =D51+M51 -> 315 | X51: =E51+N51 -> 6 | Y51: =F51+O51 -> 1026 | Z51: =G51+P51 -> 1 | AA51: =H51+Q51 -> 5 | AB51: =I51+R51 -> 629 | AC51: =J51+S51 -> 2358 | AD51: =K51+T51 -> 515 | AE51: =L51+U51 -> 6 | AF51: =SUM(W51:AE51) -> 4861
B52: JUMLAH SEWILAYAH JAWA BARAT | D52: =SUM(D24:D51) -> 778 | E52: =SUM(E24:E51) -> 1298 | F52: =SUM(F24:F51) -> 18274 | G52: =SUM(G24:G51) -> 190 | H52: =SUM(H24:H51) -> 1368 | I52: =SUM(I24:I51) -> 20054 | J52: =SUM(J24:J51) -> 138350 | K52: =SUM(K24:K51) -> 30093 | ... V52: =SUM(V24:V51) -> 378744 | W52: =D52+M52 -> 2264 | X52: =E52+N52 -> 2257 | Y52: =F52+O52 -> 33118 | Z52: =G52+P52 -> 190 | AA52: =H52+Q52 -> 1390 | AB52: =I52+R52 -> 37170 | AC52: =J52+S52 -> 268335 | AD52: =K52+T52 -> 33513 | AE52: =L52+U52 -> 507 | AF52: =SUM(W52:AE52) -> 378744
B53: 6200 | C53: Pemerintah Provinsi Banten | D53: 3 | E53: 29 | F53: 454 | G53: 1 | H53: 6 | I53: 249 | J53: 4665 | K53: 2800 | L53: 73 | M53: 82 | N53: 9 | O53: 2864 | P53: 0 | Q53: 0 | R53: 470 | S53: 9834 | T53: 116 | U53: 0 | V53: =SUM(D53:U53) -> 21655 | W53: =D53+M53 -> 85 | X53: =E53+N53 -> 38 | Y53: =F53+O53 -> 3318 | Z53: =G53+P53 -> 1 | AA53: =H53+Q53 -> 6 | AB53: =I53+R53 -> 719 | AC53: =J53+S53 -> 14499 | AD53: =K53+T53 -> 2916 | AE53: =L53+U53 -> 73 | AF53: =SUM(W53:AE53) -> 21655
